Workbook

Sheet TKP 终端汇总
A1: TKP 2024年NPI报表（1-6月）-按客户终端汇总
A2: 币别:HKD
A3: 终端客户 | B3: 量产前收入 | C3: 量产前成本 | D3: 量产前收益 | E3: 量产后成本 | F3: 项目收益 | G3: 原因分析
A4: BAT | B4: =SUMIF('TKP 项目汇总'!D:D,'TKP 终端汇总'!A:A,'TKP 项目汇总'!M:M) -> 1915072 | C4: =SUMIF('TKP 项目汇总'!$D:$D,'TKP 终端汇总'!$A:$A,'TKP 项目汇总'!$S:$S) -> 28056360 | D4: =SUMIF('TKP 项目汇总'!$D:$D,'TKP 终端汇总'!$A:$A,'TKP 项目汇总'!$T:$T) -> -26141288 | E4: =SUMIF('TKP 项目汇总'!$D:$D,'TKP 终端汇总'!$A:$A,'TKP 项目汇总'!$W:$W) -> 244088.39 | F4: =SUMIF('TKP 项目汇总'!$D:$D,'TKP 终端汇总'!$A:$A,'TKP 项目汇总'!$X:$X) -> -26385376
A5: 合元 | B5: =SUMIF('TKP 项目汇总'!D:D,'TKP 终端汇总'!A:A,'TKP 项目汇总'!M:M) -> 7116459.5 | C5: =SUMIF('TKP 项目汇总'!$D:$D,'TKP 终端汇总'!$A:$A,'TKP 项目汇总'!$S:$S) -> 11709292 | D5: =SUMIF('TKP 项目汇总'!$D:$D,'TKP 终端汇总'!$A:$A,'TKP 项目汇总'!$T:$T) -> -4592833 | E5: =SUMIF('TKP 项目汇总'!$D:$D,'TKP 终端汇总'!$A:$A,'TKP 项目汇总'!$W:$W) -> 123669.23 | F5: =SUMIF('TKP 项目汇总'!$D:$D,'TKP 终端汇总'!$A:$A,'TKP 项目汇总'!$X:$X) -> -4716502.3
A6: Sonos | B6: =SUMIF('TKP 项目汇总'!D:D,'TKP 终端汇总'!A:A,'TKP 项目汇总'!M:M) -> 11023040 | C6: =SUMIF('TKP 项目汇总'!$D:$D,'TKP 终端汇总'!$A:$A,'TKP 项目汇总'!$S:$S) -> 12366751 | D6: =SUMIF('TKP 项目汇总'!$D:$D,'TKP 终端汇总'!$A:$A,'TKP 项目汇总'!$T:$T) -> -1343710.5 | E6: =SUMIF('TKP 项目汇总'!$D:$D,'TKP 终端汇总'!$A:$A,'TKP 项目汇总'!$W:$W) -> 1123794.8 | F6: =SUMIF('TKP 项目汇总'!$D:$D,'TKP 终端汇总'!$A:$A,'TKP 项目汇总'!$X:$X) -> -2467505.3
A7: 通力 | B7: =SUMIF('TKP 项目汇总'!D:D,'TKP 终端汇总'!A:A,'TKP 项目汇总'!M:M) -> 2701479.6 | C7: =SUMIF('TKP 项目汇总'!$D:$D,'TKP 终端汇总'!$A:$A,'TKP 项目汇总'!$S:$S) -> 4972751.8 | D7: =SUMIF('TKP 项目汇总'!$D:$D,'TKP 终端汇总'!$A:$A,'TKP 项目汇总'!$T:$T) -> -2271272.3 | E7: =SUMIF('TKP 项目汇总'!$D:$D,'TKP 终端汇总'!$A:$A,'TKP 项目汇总'!$W:$W) -> 116964.66 | F7: =SUMIF('TKP 项目汇总'!$D:$D,'TKP 终端汇总'!$A:$A,'TKP 项目汇总'!$X:$X) -> -2388236.9
A8: 韶音 | B8: =SUMIF('TKP 项目汇总'!D:D,'TKP 终端汇总'!A:A,'TKP 项目汇总'!M:M) -> 846468.08 | C8: =SUMIF('TKP 项目汇总'!$D:$D,'TKP 终端汇总'!$A:$A,'TKP 项目汇总'!$S:$S) -> 2065434.7 | D8: =SUMIF('TKP 项目汇总'!$D:$D,'TKP 终端汇总'!$A:$A,'TKP 项目汇总'!$T:$T) -> -1218966.6 | E8: =SUMIF('TKP 项目汇总'!$D:$D,'TKP 终端汇总'!$A:$A,'TKP 项目汇总'!$W:$W) -> 324641.65 | F8: =SUMIF('TKP 项目汇总'!$D:$D,'TKP 终端汇总'!$A:$A,'TKP 项目汇总'!$X:$X) -> -1543608.2
A9: Google | B9: =SUMIF('TKP 项目汇总'!D:D,'TKP 终端汇总'!A:A,'TKP 项目汇总'!M:M) -> 4113660.1 | C9: =SUMIF('TKP 项目汇总'!$D:$D,'TKP 终端汇总'!$A:$A,'TKP 项目汇总'!$S:$S) -> 4095308.3 | D9: =SUMIF('TKP 项目汇总'!$D:$D,'TKP 终端汇总'!$A:$A,'TKP 项目汇总'!$T:$T) -> 18351.82 | E9: =SUMIF('TKP 项目汇总'!$D:$D,'TKP 终端汇总'!$A:$A,'TKP 项目汇总'!$W:$W) -> 365605.18 | F9: =SUMIF('TKP 项目汇总'!$D:$D,'TKP 终端汇总'!$A:$A,'TKP 项目汇总'!$X:$X) -> -347253.36
A10: August | B10: =SUMIF('TKP 项目汇总'!D:D,'TKP 终端汇总'!A:A,'TKP 项目汇总'!M:M) -> 768103.15 | C10: =SUMIF('TKP 项目汇总'!$D:$D,'TKP 终端汇总'!$A:$A,'TKP 项目汇总'!$S:$S) -> 1002916.6 | D10: =SUMIF('TKP 项目汇总'!$D:$D,'TKP 终端汇总'!$A:$A,'TKP 项目汇总'!$T:$T) -> -234813.49 | E10: =SUMIF('TKP 项目汇总'!$D:$D,'TKP 终端汇总'!$A:$A,'TKP 项目汇总'!$W:$W) -> 107742.62 | F10: =SUMIF('TKP 项目汇总'!$D:$D,'TKP 终端汇总'!$A:$A,'TKP 项目汇总'!$X:$X) -> -342556.11
A11: AMAZON | B11: =SUMIF('TKP 项目汇总'!D:D,'TKP 终端汇总'!A:A,'TKP 项目汇总'!M:M) -> 0 | C11: =SUMIF('TKP 项目汇总'!$D:$D,'TKP 终端汇总'!$A:$A,'TKP 项目汇总'!$S:$S) -> 232604.77 | D11: =SUMIF('TKP 项目汇总'!$D:$D,'TKP 终端汇总'!$A:$A,'TKP 项目汇总'!$T:$T) -> -232604.77 | E11: =SUMIF('TKP 项目汇总'!$D:$D,'TKP 终端汇总'!$A:$A,'TKP 项目汇总'!$W:$W) -> 80767.77 | F11: =SUMIF('TKP 项目汇总'!$D:$D,'TKP 终端汇总'!$A:$A,'TKP 项目汇总'!$X:$X) -> -313372.54
A12: 索尼电子 | B12: =SUMIF('TKP 项目汇总'!D:D,'TKP 终端汇总'!A:A,'TKP 项目汇总'!M:M) -> 1032298.2 | C12: =SUMIF('TKP 项目汇总'!$D:$D,'TKP 终端汇总'!$A:$A,'TKP 项目汇总'!$S:$S) -> 1329526.2 | D12: =SUMIF('TKP 项目汇总'!$D:$D,'TKP 终端汇总'!$A:$A,'TKP 项目汇总'!$T:$T) -> -297228.05 | E12: =SUMIF('TKP 项目汇总'!$D:$D,'TKP 终端汇总'!$A:$A,'TKP 项目汇总'!$W:$W) -> 0 | F12: =SUMIF('TKP 项目汇总'!$D:$D,'TKP 终端汇总'!$A:$A,'TKP 项目汇总'!$X:$X) -> -297228.05
A13: 歌尔 | B13: =SUMIF('TKP 项目汇总'!D:D,'TKP 终端汇总'!A:A,'TKP 项目汇总'!M:M) -> 48163.01 | C13: =SUMIF('TKP 项目汇总'!$D:$D,'TKP 终端汇总'!$A:$A,'TKP 项目汇总'!$S:$S) -> 327228.73 | D13: =SUMIF('TKP 项目汇总'!$D:$D,'TKP 终端汇总'!$A:$A,'TKP 项目汇总'!$T:$T) -> -279065.72 | E13: =SUMIF('TKP 项目汇总'!$D:$D,'TKP 终端汇总'!$A:$A,'TKP 项目汇总'!$W:$W) -> 1098.26 | F13: =SUMIF('TKP 项目汇总'!$D:$D,'TKP 终端汇总'!$A:$A,'TKP 项目汇总'!$X:$X) -> -280163.98
A14: 影石 | B14: =SUMIF('TKP 项目汇总'!D:D,'TKP 终端汇总'!A:A,'TKP 项目汇总'!M:M) -> 1291063.3 | C14: =SUMIF('TKP 项目汇总'!$D:$D,'TKP 终端汇总'!$A:$A,'TKP 项目汇总'!$S:$S) -> 1379274.3 | D14: =SUMIF('TKP 项目汇总'!$D:$D,'TKP 终端汇总'!$A:$A,'TKP 项目汇总'!$T:$T) -> -88211 | E14: =SUMIF('TKP 项目汇总'!$D:$D,'TKP 终端汇总'!$A:$A,'TKP 项目汇总'!$W:$W) -> 158719.22 | F14: =SUMIF('TKP 项目汇总'!$D:$D,'TKP 终端汇总'!$A:$A,'TKP 项目汇总'!$X:$X) -> -246930.22
A15: 爱立康 | B15: =SUMIF('TKP 项目汇总'!D:D,'TKP 终端汇总'!A:A,'TKP 项目汇总'!M:M) -> 501666.11 | C15: =SUMIF('TKP 项目汇总'!$D:$D,'TKP 终端汇总'!$A:$A,'TKP 项目汇总'!$S:$S) -> 742401.23 | D15: =SUMIF('TKP 项目汇总'!$D:$D,'TKP 终端汇总'!$A:$A,'TKP 项目汇总'!$T:$T) -> -240735.12 | E15: =SUMIF('TKP 项目汇总'!$D:$D,'TKP 终端汇总'!$A:$A,'TKP 项目汇总'!$W:$W) -> 0 | F15: =SUMIF('TKP 项目汇总'!$D:$D,'TKP 终端汇总'!$A:$A,'TKP 项目汇总'!$X:$X) -> -240735.12
... A92: BigScreen | B92: =SUMIF('TKP 项目汇总'!D:D,'TKP 终端汇总'!A:A,'TKP 项目汇总'!M:M) -> 823788.54 | C92: =SUMIF('TKP 项目汇总'!$D:$D,'TKP 终端汇总'!$A:$A,'TKP 项目汇总'!$S:$S) -> 7488.99 | D92: =SUMIF('TKP 项目汇总'!$D:$D,'TKP 终端汇总'!$A:$A,'TKP 项目汇总'!$T:$T) -> 816299.55 | E92: =SUMIF('TKP 项目汇总'!$D:$D,'TKP 终端汇总'!$A:$A,'TKP 项目汇总'!$W:$W) -> 10271.46 | F92: =SUMIF('TKP 项目汇总'!$D:$D,'TKP 终端汇总'!$A:$A,'TKP 项目汇总'!$X:$X) -> 806028.09
A93: 总计： | B93: =SUM(B4:B92) -> 50828982 | C93: =SUM(C4:C92) -> 83937409 | D93: =SUM(D4:D92) -> -33108427 | E93: =SUM(E4:E92) -> 4088386.5 | F93: =SUM(F4:F92) -> -37196814
B94: =B93-'TKP 项目汇总'!M393 -> 0 | C94: =C93-'TKP 项目汇总'!S393 -> 0 | D94: =D93-'TKP 项目汇总'!T393 -> 0 | E94: =E93-'TKP 项目汇总'!W393 -> 0 | F94: =F93-'TKP 项目汇总'!X393 -> 0
A96: TKP 2024年NPI报表（1-6月）-按BU汇总
A97: 币别:HKD
A98: 事业部 | B98: 量产前收入 | C98: 量产前成本 | D98: 量产前收益 | E98: 量产后成本 | F98: 项目收益 | G98: 原因分析
A99: HP1 | B99: ='HP1'!$O$58 -> 8818552.2 | C99: ='HP1'!$U$58 -> 10737954 | D99: =B99-C99 -> -1919401.9 | E99: ='HP1'!$Y$58 -> 161623.03 | F99: =D99-E99 -> -2081025
A100: HP3 | B100: ='HP3'!O55 -> 5800873 | C100: ='HP3'!U55 -> 5328200.8 | D100: =B100-C100 -> 472672.13 | E100: ='HP3'!Y55 -> 106770.27 | F100: =D100-E100 -> 365901.86
A101: HP4 | B101: ='HP4'!O55 -> 8819603.8 | C101: ='HP4'!U55 -> 37052015 | D101: =B101-C101 -> -28232412 | E101: ='HP4'!Y55 -> 354814.42 | F101: =D101-E101 -> -28587226
A102: SD1 | B102: ='SD1'!O91 -> 3805816.1 | C102: ='SD1'!U91 -> 3248089.4 | D102: =B102-C102 -> 557726.74 | E102: ='SD1'!Y91 -> 772244.11 | F102: =D102-E102 -> -214517.37
A103: MDT | B103: =MDT!O10 -> 698609.53 | C103: =MDT!U10 -> 83686.12 | D103: =B103-C103 -> 614923.41 | E103: =MDT!Y10 -> 8087.78 | F103: =D103-E103 -> 606835.63
A104: HCT | B104: =HCT!O34 -> 609552.03 | C104: =HCT!U34 -> 358293.82 | D104: =B104-C104 -> 251258.21 | E104: =HCT!Y34 -> 32984.27 | F104: =D104-E104 -> 218273.94
A105: HZ1 | B105: ='HZ1 '!O91 -> 12687346 | C105: ='HZ1 '!U91 -> 18205147 | D105: =B105-C105 -> -5517801.1 | E105: ='HZ1 '!Y91 -> 2036960.9 | F105: =D105-E105 -> -7554762
A106: HD1 | B106: ='HD1'!O39 -> 2110942 | C106: ='HD1'!U39 -> 1844751.6 | D106: =B106-C106 -> 266190.43 | E106: ='HD1'!Y39 -> 160958.39 | F106: =D106-E106 -> 105232.04
A107: HD2 | B107: ='HD2'!O50 -> 6850217 | C107: ='HD2'!U50 -> 5509725.9 | D107: =B107-C107 -> 1340491.1 | E107: ='HD2'!Y50 -> 242763.85 | F107: =D107-E107 -> 1097727.2
A108: TKTC | B108: =TKTC!O50 -> 627470.58 | C108: =TKTC!U50 -> 899108.08 | D108: =B108-C108 -> -271637.5 | E108: =TKTC!Y50 -> 182444.67 | F108: =D108-E108 -> -454082.17
A109: TKYN | B109: =TKYN!O19 -> 0 | C109: =TKYN!U19 -> 562417.84 | D109: =B109-C109 -> -562417.84 | E109: =TKYN!Y19 -> 28734.78 | F109: =D109-E109 -> -591152.62
A110: PDS | B110: =PDS!O6 -> 0 | C110: =PDS!U6 -> 108019.21 | D110: =B110-C110 -> -108019.21 | E110: =PDS!Y6 -> 0 | F110: =D110-E110 -> -108019.21
A111: 合计 | B111: =SUM(B99:B110) -> 50828982 | C111: =SUM(C99:C110) -> 83937409 | D111: =SUM(D99:D110) -> -33108427 | E111: =SUM(E99:E110) -> 4088386.5 | F111: =SUM(F99:F110) -> -37196814
D112: =D111-'TKP 项目汇总'!T393 -> 0.03999998 | F112: =F111-'TKP 项目汇总'!X393 -> 0.030999996

Sheet TKP 项目汇总
A1: TKP 2024年1-6月NPI报表明细
A2: 币别:HKD
A3: TK项目号 | B3: 项目名称 | C3: 终端客户 | D3: 终端客户名称 | E3: 创建日期 | F3: 量产日期 | G3: NPI预算收入 | H3: 注塑模具收入 | I3: 其他模具收入 | J3: 样板费收入 | K3: 夹治具收入 | L3: 其它杂项收入 | M3: 量产前收入 | N3: 注塑模具成本 | O3: 其他模具成本 | P3: 自费模具摊销 | Q3: 夹治具成本 | R3: 试模成本 | S3: 量产前成本 | T3: 量产前收益 | U3: 量产后夹治具成本 | V3: 量产后打样成本 | W3: 量产后成本 | X3: 项目收益
A4: P440075 | B4: JAMS-0097 | C4: 440 | D4: OTTERBOX | E4: 44698 | F4: 44838 | G4: 15668730 | H4: 0 | I4: 0 | J4: 83983.05 | K4: 0 | L4: 0 | M4: 83983.05 | N4: 0 | O4: 0 | P4: 0 | Q4: 0 | R4: 57554.78 | S4: 57554.78 | T4: 26428.27 | U4: 2003.31 | V4: 0 | W4: 2003.31 | X4: 24424.96 | Y4: =VLOOKUP(D4,'TKP 终端汇总'!A:A,1,0) -> OTTERBOX
A5: P831004 | B5: IO LOCK | C5: C831 | D5: August | E5: 44503 | G5: 1686960 | H5: 730384.2 | I5: 0 | J5: 2962.88 | K5: 0 | L5: 0 | M5: 733347.08 | N5: 747658.93 | O5: 0 | P5: 0 | Q5: 0 | R5: 4282.35 | S5: 751941.28 | T5: -18594.2 | U5: 0 | V5: 47.65 | W5: 47.65 | X5: -18641.85 | Y5: =VLOOKUP(D5,'TKP 终端汇总'!A:A,1,0) -> August
A6: P201010 | B6: 反应杯-16腔六联杯 | C6: C201 | D6: 新产业 | E6: 44616 | F6: 44848 | G6: 5247000 | H6: 576713.82 | I6: 0 | J6: 0 | K6: 0 | L6: 0 | M6: 576713.82 | N6: 0 | O6: 0 | P6: 0 | Q6: 0 | R6: 0 | S6: 0 | T6: 576713.82 | U6: 0 | V6: 2530.34 | W6: 2530.34 | X6: 574183.48 | Y6: =VLOOKUP(D6,'TKP 终端汇总'!A:A,1,0) -> 新产业
A7: P440074 | B7: JAMS-0277 | C7: 440 | D7: OTTERBOX | E7: 44698 | F7: 44826 | G7: 0 | H7: 0 | I7: 0 | J7: 0 | K7: 0 | L7: 0 | M7: 0 | N7: 0 | O7: 0 | P7: 0 | Q7: 0 | R7: 0 | S7: 0 | T7: 0 | U7: 0 | V7: 0 | W7: 0 | X7: 0 | Y7: =VLOOKUP(D7,'TKP 终端汇总'!A:A,1,0) -> OTTERBOX
A8: P440076 | B8: JAMS-0085 | C8: 440 | D8: OTTERBOX | E8: 44698 | F8: 44830 | G8: 7643856 | H8: 0 | I8: 0 | J8: 0 | K8: 0 | L8: 0 | M8: 0 | N8: 0 | O8: 0 | P8: 0 | Q8: 1900.51 | R8: 0 | S8: 1900.51 | T8: -1900.51 | U8: 34953.85 | V8: 0 | W8: 34953.85 | X8: -36854.36 | Y8: =VLOOKUP(D8,'TKP 终端汇总'!A:A,1,0) -> OTTERBOX
A9: P440072 | B9: JAMS-0193 | C9: 440 | D9: OTTERBOX | E9: 44698 | G9: 0 | H9: 0 | I9: 0 | J9: 0 | K9: 0 | L9: 0 | M9: 0 | N9: 0 | O9: 0 | P9: 0 | Q9: 0 | R9: 0 | S9: 0 | T9: 0 | U9: 0 | V9: 0 | W9: 0 | X9: 0 | Y9: =VLOOKUP(D9,'TKP 终端汇总'!A:A,1,0) -> OTTERBOX
A10: P440080 | B10: JAMS-0041 | C10: 440 | D10: OTTERBOX | E10: 44699 | F10: 44830 | G10: 0 | H10: 0 | I10: 0 | J10: 0 | K10: 0 | L10: 0 | M10: 0 | N10: 0 | O10: 0 | P10: 0 | Q10: 0 | R10: 0 | S10: 0 | T10: 0 | U10: 0 | V10: 0 | W10: 0 | X10: 0 | Y10: =VLOOKUP(D10,'TKP 终端汇总'!A:A,1,0) -> OTTERBOX
A11: P440073 | B11: JAMS-0227 | C11: 440 | D11: OTTERBOX | E11: 44698 | F11: 44826 | G11: 0 | H11: 0 | I11: 0 | J11: 0 | K11: 0 | L11: 0 | M11: 0 | N11: 0 | O11: 0 | P11: 0 | Q11: 0 | R11: -9156.37 | S11: -9156.37 | T11: 9156.37 | U11: 0 | V11: 0 | W11: 0 | X11: 9156.37 | Y11: =VLOOKUP(D11,'TKP 终端汇总'!A:A,1,0) -> OTTERBOX
A12: P833002 | B12: 眼部植入T型管 | C12: C833 | D12: 润视 | E12: 44427 | G12: 93305.3 | H12: 0 | I12: 0 | J12: 0 | K12: 0 | L12: 0 | M12: 0 | N12: 2923.87 | O12: 0 | P12: 0 | Q12: 0 | R12: 0 | S12: 2923.87 | T12: -2923.87 | U12: 0 | V12: 0 | W12: 0 | X12: -2923.87 | Y12: =VLOOKUP(D12,'TKP 终端汇总'!A:A,1,0) -> 润视
A13: P330040 | B13: SAMWISE | C13: 330 | D13: GN | E13: 44482 | G13: 19323850 | H13: 178849 | I13: 0 | J13: 13557.21 | K13: 0 | L13: 0 | M13: 192406.21 | N13: 106233.68 | O13: 0 | P13: 9788.82 | Q13: 0 | R13: 10150.58 | S13: 126173.08 | T13: 66233.13 | U13: 2079.44 | V13: 425.67 | W13: 2505.11 | X13: 63728.02 | Y13: =VLOOKUP(D13,'TKP 终端汇总'!A:A,1,0) -> GN
A14: P805023 | B14: KFC | C14: C805 | D14: 合元 | E14: 44461 | G14: 136000 | H14: 0 | I14: 0 | J14: 0 | K14: 0 | L14: 0 | M14: 0 | N14: 0 | O14: 0 | P14: 308.58 | Q14: 0 | R14: 0 | S14: 308.58 | T14: -308.58 | U14: 0 | V14: 0 | W14: 0 | X14: -308.58 | Y14: =VLOOKUP(D14,'TKP 终端汇总'!A:A,1,0) -> 合元
A15: P863001 | B15: WTH13 | C15: C863 | D15: Stripe | E15: 44628 | G15: 15365460 | H15: 0 | I15: 0 | J15: 4657.88 | K15: 4686 | L15: 0 | M15: 9343.88 | N15: 0 | O15: 0 | P15: 185333.27 | Q15: 0 | R15: 2749.9 | S15: 188083.17 | T15: -178739.29 | U15: 369.77 | V15: 10195.97 | W15: 10565.74 | X15: -189305.03 | Y15: =VLOOKUP(D15,'TKP 终端汇总'!A:A,1,0) -> Stripe
A16: P805024 | B16: PD2 | C16: C805 | D16: 合元 | E16: 44558 | G16: 0 | H16: 0 | I16: 0 | J16: 0 | K16: 0 | L16: 0 | M16: 0 | N16: 0 | O16: 0 | P16: 0 | Q16: 0 | R16: 0 | S16: 0 | T16: 0 | U16: 0 | V16: 0 | W16: 0 | X16: 0 | Y16: =VLOOKUP(D16,'TKP 终端汇总'!A:A,1,0) -> 合元
A17: P857001 | B17: AUDIGO INTRO | C17: C857 | D17: Audigo | E17: 44461 | G17: 1900000 | H17: 0 | I17: 0 | J17: 0 | K17: 0 | L17: 0 | M17: 0 | N17: 0 | O17: 0 | P17: 0 | Q17: 0 | R17: 0 | S17: 0 | T17: 0 | U17: 0 | V17: 12178.5 | W17: 12178.5 | X17: -12178.5 | Y17: =VLOOKUP(D17,'TKP 终端汇总'!A:A,1,0) -> Audigo
A18: P330041 | B18: WILLOW | C18: 330 | D18: GN | E18: 44487 | G18: 50367000 | H18: 43635.9 | I18: 0 | J18: 0 | K18: 0 | L18: 0 | M18: 43635.9 | N18: 42091.21 | O18: 0 | P18: 21652.58 | Q18: 20047.54 | R18: 0 | S18: 83791.33 | T18: -40155.43 | U18: 0 | V18: 2116.79 | W18: 2116.79 | X18: -42272.22 | Y18: =VLOOKUP(D18,'TKP 终端汇总'!A:A,1,0) -> GN
A19: P360022 | B19: C9 | C19: 360 | D19: Google | E19: 44638 | G19: 2420000 | H19: 0 | I19: 0 | J19: 0 | K19: 0 | L19: 0 | M19: 0 | N19: 0 | O19: 0 | P19: 868.98 | Q19: 0 | R19: 0 | S19: 868.98 | T19: -868.98 | U19: 0 | V19: 0 | W19: 0 | X19: -868.98 | Y19: =VLOOKUP(D19,'TKP 终端汇总'!A:A,1,0) -> Google
A20: P360023 | B20: ZERO DRAFT ADAPTOR | C20: 360 | D20: Google | E20: 44657 | G20: 836000 | H20: 0 | I20: 0 | J20: 0 | K20: 0 | L20: 0 | M20: 0 | N20: 0 | O20: 0 | P20: 2484.52 | Q20: 0 | R20: 0 | S20: 2484.52 | T20: -2484.52 | U20: 0 | V20: 0 | W20: 0 | X20: -2484.52 | Y20: =VLOOKUP(D20,'TKP 终端汇总'!A:A,1,0) -> Google
A21: P831005 | B21: 400 SERIES | C21: C831 | D21: August | E21: 44607 | G21: 4711014 | H21: 0 | I21: 0 | J21: 0 | K21: 0 | L21: 0 | M21: 0 | N21: 190.93 | O21: 0 | P21: 6982.16 | Q21: 2836.66 | R21: 5618.34 | S21: 15628.09 | T21: -15628.09 | U21: 12036.72 | V21: 62837.67 | W21: 74874.39 | X21: -90502.48 | Y21: =VLOOKUP(D21,'TKP 终端汇总'!A:A,1,0) -> August
A22: P805027 | B22: COROLLA | C22: C805 | D22: 合元 | E22: 44677 | G22: 20095000 | H22: 205248.64 | I22: 0 | J22: 0 | K22: 0 | L22: 0 | M22: 205248.64 | N22: 25122.16 | O22: 0 | P22: 37023.95 | Q22: 0 | R22: 0 | S22: 62146.11 | T22: 143102.53 | U22: 0 | V22: 40.42 | W22: 40.42 | X22: 143062.11 | Y22: =VLOOKUP(D22,'TKP 终端汇总'!A:A,1,0) -> 合元
A23: P862001 | B23: PSC56一体机 | C23: C862 | D23: 影石 | E23: 44606 | G23: 10261764 | H23: 81135.91 | I23: 0 | J23: 15261 | K23: 0 | L23: 0 | M23: 96396.91 | N23: 19288.38 | O23: 0 | P23: 10491.48 | Q23: 25292.97 | R23: 0 | S23: 55072.83 | T23: 41324.08 | U23: 0 | V23: 107227.17 | W23: 107227.17 | X23: -65903.09 | Y23: =VLOOKUP(D23,'TKP 终端汇总'!A:A,1,0) -> 影石
A24: P860002 | B24: SKELLIG | C24: C860 | D24: 通力 | E24: 44634 | G24: 0 | H24: 0 | I24: 0 | J24: 0 | K24: 0 | L24: 0 | M24: 0 | N24: 0 | O24: 0 | P24: 0 | Q24: 0 | R24: 0 | S24: 0 | T24: 0 | U24: 0 | V24: 0 | W24: 0 | X24: 0 | Y24: =VLOOKUP(D24,'TKP 终端汇总'!A:A,1,0) -> 通力
A25: P330042 | B25: PILLOW | C25: 330 | D25: GN | E25: 44496 | G25: 7104600 | H25: 0 | I25: 0 | J25: 0 | K25: 0 | L25: 0 | M25: 0 | N25: 0 | O25: 0 | P25: 1845.53 | Q25: 0 | R25: 0 | S25: 1845.53 | T25: -1845.53 | U25: 0 | V25: 289.66 | W25: 289.66 | X25: -2135.19 | Y25: =VLOOKUP(D25,'TKP 终端汇总'!A:A,1,0) -> GN
A26: P866002 | B26: F02 | C26: C866 | D26: Meta | E26: 44691 | G26: 18102000 | H26: 0 | I26: 0 | J26: 0 | K26: 0 | L26: 0 | M26: 0 | N26: 0 | O26: 0 | P26: 0 | Q26: 0 | R26: 0 | S26: 0 | T26: 0 | U26: 0 | V26: 9714.13 | W26: 9714.13 | X26: -9714.13 | Y26: =VLOOKUP(D26,'TKP 终端汇总'!A:A,1,0) -> Meta
A27: P805022 | B27: HW42410 | C27: C805 | D27: 合元 | E27: 44456 | G27: 874800 | H27: 10119.23 | I27: 0 | J27: 0 | K27: 0 | L27: 0 | M27: 10119.23 | N27: 0 | O27: 0 | P27: 0 | Q27: 0 | R27: 0 | S27: 0 | T27: 10119.23 | U27: 0 | V27: 0 | W27: 0 | X27: 10119.23 | Y27: =VLOOKUP(D27,'TKP 终端汇总'!A:A,1,0) -> 合元
A28: P438045 | B28: OSAKA | C28: 438 | D28: PHILIPS | E28: 44516 | G28: 7342600 | H28: 0 | I28: 0 | J28: 120388.34 | K28: 0 | L28: 0 | M28: 120388.34 | N28: 0 | O28: 0 | P28: 0 | Q28: 0 | R28: 0 | S28: 0 | T28: 120388.34 | U28: 0 | V28: 3166.03 | W28: 3166.03 | X28: 117222.31 | Y28: =VLOOKUP(D28,'TKP 终端汇总'!A:A,1,0) -> PHILIPS
A29: P866003 | B29: F03 | C29: C866 | D29: Meta | E29: 44700 | G29: 0 | H29: 0 | I29: 0 | J29: 0 | K29: 0 | L29: 0 | M29: 0 | N29: 0 | O29: 0 | P29: 0 | Q29: 0 | R29: 0 | S29: 0 | T29: 0 | U29: 0 | V29: 0 | W29: 0 | X29: 0 | Y29: =VLOOKUP(D29,'TKP 终端汇总'!A:A,1,0) -> Meta
A30: P438044 | B30: ZETA | C30: 438 | D30: PHILIPS | E30: 44442 | G30: 660000 | H30: 0 | I30: 0 | J30: 41007.48 | K30: 172.38 | L30: 0 | M30: 41179.86 | N30: 5698.39 | O30: 0 | P30: 6663.15 | Q30: 0 | R30: 34528.65 | S30: 46890.19 | T30: -5710.33 | U30: 0 | V30: 53736.09 | W30: 53736.09 | X30: -59446.42 | Y30: =VLOOKUP(D30,'TKP 终端汇总'!A:A,1,0) -> PHILIPS
A31: P440071 | B31: TECHDEV 2022 | C31: 440 | D31: OTTERBOX | E31: 44623 | G31: 0 | H31: 0 | I31: 0 | J31: 0 | K31: 0 | L31: 0 | M31: 0 | N31: 0 | O31: 0 | P31: 0 | Q31: 0 | R31: 0 | S31: 0 | T31: 0 | U31: 0 | V31: 0 | W31: 0 | X31: 0 | Y31: =VLOOKUP(D31,'TKP 终端汇总'!A:A,1,0) -> OTTERBOX
A32: P821003 | B32: S3 MOUNT | C32: C821 | D32: Square | E32: 44480 | G32: 13080000 | H32: 0 | I32: 0 | J32: 0 | K32: 0 | L32: 0 | M32: 0 | N32: 0 | O32: 0 | P32: 9094.98 | Q32: 0 | R32: 0 | S32: 9094.98 | T32: -9094.98 | U32: 0 | V32: 0 | W32: 0 | X32: -9094.98 | Y32: =VLOOKUP(D32,'TKP 终端汇总'!A:A,1,0) -> Square
A33: P438048 | B33: GAEA 1 | C33: 438 | D33: PHILIPS | E33: 44677 | G33: 0 | H33: 0 | I33: 0 | J33: 0 | K33: 0 | L33: 0 | M33: 0 | N33: 0 | O33: 0 | P33: 0 | Q33: 0 | R33: 0 | S33: 0 | T33: 0 | U33: 0 | V33: 0 | W33: 0 | X33: 0 | Y33: =VLOOKUP(D33,'TKP 终端汇总'!A:A,1,0) -> PHILIPS
A34: P438049 | B34: CAIRO | C34: 438 | D34: PHILIPS | E34: 44706 | G34: 25730568 | H34: 0 | I34: 0 | J34: 315522.76 | K34: 0 | L34: 0 | M34: 315522.76 | N34: 0 | O34: 0 | P34: 2576.15 | Q34: 0 | R34: 48234.58 | S34: 50810.73 | T34: 264712.03 | U34: 0 | V34: 0 | W34: 0 | X34: 264712.03 | Y34: =VLOOKUP(D34,'TKP 终端汇总'!A:A,1,0) -> PHILIPS
A35: P805026 | B35: PLUZE 1.5 | C35: C805 | D35: 合元 | E35: 44670 | G35: 26807280 | H35: 0 | I35: 0 | J35: 76914.16 | K35: 0 | L35: 0 | M35: 76914.16 | N35: 45349.59 | O35: 0 | P35: 4167.69 | Q35: 3053.06 | R35: 614.57 | S35: 53184.91 | T35: 23729.25 | U35: 0 | V35: 7287.47 | W35: 7287.47 | X35: 16441.78 | Y35: =VLOOKUP(D35,'TKP 终端汇总'!A:A,1,0) -> 合元
A36: P866001 | B36: F01 | C36: C866 | D36: Meta | E36: 44674 | G36: 2220000 | H36: 0 | I36: 0 | J36: 0 | K36: 0 | L36: 0 | M36: 0 | N36: 0 | O36: 0 | P36: 0 | Q36: 3851.82 | R36: 0 | S36: 3851.82 | T36: -3851.82 | U36: 0 | V36: 0 | W36: 0 | X36: -3851.82 | Y36: =VLOOKUP(D36,'TKP 终端汇总'!A:A,1,0) -> Meta
A37: P861002 | B37: SQUARE | C37: C861 | D37: 合元 | E37: 44623 | G37: 13134000 | H37: 295939.9 | I37: 0 | J37: 0 | K37: 0 | L37: 0 | M37: 295939.9 | N37: 149728.26 | O37: 0 | P37: 3148.49 | Q37: 0 | R37: 0 | S37: 152876.75 | T37: 143063.15 | U37: 2711.19 | V37: 4644.01 | W37: 7355.2 | X37: 135707.95 | Y37: =VLOOKUP(D37,'TKP 终端汇总'!A:A,1,0) -> 合元
A38: P824006 | B38: MD2.0 | C38: C824 | D38: BAT | E38: 44729 | G38: 4796000 | H38: 0 | I38: 0 | J38: 0 | K38: 0 | L38: 0 | M38: 0 | N38: 0 | O38: 0 | P38: 21775.83 | Q38: 0 | R38: 0 | S38: 21775.83 | T38: -21775.83 | U38: 0 | V38: 0 | W38: 0 | X38: -21775.83 | Y38: =VLOOKUP(D38,'TKP 终端汇总'!A:A,1,0) -> BAT
A39: P805025 | B39: MOTO | C39: C805 | D39: 合元 | E39: 44652 | G39: 55264500 | H39: 1262215.6 | I39: 0 | J39: 0 | K39: 0 | L39: 0 | M39: 1262215.6 | N39: 3053703 | O39: 0 | P39: 514608.27 | Q39: 0 | R39: 3052.5 | S39: 3571363.8 | T39: -2309148.2 | U39: 0 | V39: 442.38 | W39: 442.38 | X39: -2309590.6 | Y39: =VLOOKUP(D39,'TKP 终端汇总'!A:A,1,0) -> 合元
A40: P815005 | B40: URANUS | C40: C815 | D40: 问问 | E40: 44629 | G40: 5427000 | H40: 0 | I40: 0 | J40: 0 | K40: 0 | L40: 0 | M40: 0 | N40: 2815.22 | O40: 0 | P40: 8093.37 | Q40: 0 | R40: 0 | S40: 10908.59 | T40: -10908.59 | U40: 2291.14 | V40: 141.25 | W40: 2432.39 | X40: -13340.98 | Y40: =VLOOKUP(D40,'TKP 终端汇总'!A:A,1,0) -> 问问
...

Sheet 按BU汇总
A1: TK项目号 | B1: 项目名称 | C1: 利润中心 | D1: 事业部 | E1: 终端客户 | F1: 终端客户名称 | G1: 创建日期 | H1: 量产日期 | I1: NPI预算收入 | J1: 注塑模具收入 | K1: 其他模具收入 | L1: 样板费收入 | M1: 夹治具收入 | N1: 其它杂项收入 | O1: 量产前收入 | P1: 注塑模具成本 | Q1: 其他模具成本 | R1: 自费模具摊销 | S1: 量产前夹治具成本 | T1: 试模成本 | U1: 量产前成本 | V1: 量产前收益 | W1: 量产后夹治具成本 | X1: 量产后打样成本 | Y1: 量产后成本
A2: P208003 | B2: VIE | C2: 100 | D2: 高效一 | E2: C208 | F2: 深圳市韶音科技有限公司 | G2: 44226 | H2: 44223 | I2: 1144000 | J2: 1674505.5 | K2: 0 | L2: 25419.56 | M2: 205803.66 | N2: 0 | O2: =SUM(J2:N2) -> 1905728.7 | P2: 2599941.2 | Q2: 0 | R2: 28874.55 | S2: 48321.4 | T2: 28886.58 | U2: =SUM(P2:T2) -> 2706023.7 | V2: =O2-U2 -> -800295.05 | W2: 187017.73 | X2: 46061.7 | Y2: 233079.43
A3: P330041 | B3: WILLOW | C3: 100 | D3: 高效一 | E3: 330 | F3: GN Audio A/S(GSC) | G3: 44487 | I3: 8394500 | J3: 0 | K3: 0 | L3: 33810.83 | M3: 0 | N3: 0 | O3: =SUM(J3:N3) -> 33810.83 | P3: 0 | Q3: 0 | R3: 0 | S3: 201918.66 | T3: 161321.99 | U3: =SUM(P3:T3) -> 363240.65 | V3: =O3-U3 -> -329429.82 | W3: 0 | X3: 0 | Y3: 0
A4: P435004 | B4: Dublin MONO | C4: 100 | D4: 高效一 | E4: 330 | F4: GN Audio A/S(GSC) | G4: 44226 | H4: 42181 | I4: 0 | J4: 0 | K4: 0 | L4: 0 | M4: 0 | N4: 0 | O4: =SUM(J4:N4) -> 0 | P4: 0 | Q4: 0 | R4: 5012.85 | S4: 60779.34 | T4: 4286.79 | U4: =SUM(P4:T4) -> 70078.98 | V4: =O4-U4 -> -70078.98 | W4: 0 | X4: 4972.78 | Y4: 4972.78
A5: P330020 | B5: Leo | C5: 100 | D5: 高效一 | E5: 330 | F5: GN Audio A/S(GSC) | G5: 44226 | H5: 44371 | I5: 0 | J5: 0 | K5: 0 | L5: 0 | M5: 0 | N5: 0 | O5: =SUM(J5:N5) -> 0 | P5: 0 | Q5: 0 | R5: 7894.22 | S5: 0 | T5: 0 | U5: =SUM(P5:T5) -> 7894.22 | V5: =O5-U5 -> -7894.22 | W5: 0 | X5: 1818.99 | Y5: 1818.99
A6: P360009 | B6: SABRINA | C6: 100 | D6: 高效一 | E6: 360 | F6: Google Inc. | G6: 44226 | H6: 43999 | I6: 0 | J6: 0 | K6: 0 | L6: 0 | M6: 0 | N6: 0 | O6: =SUM(J6:N6) -> 0 | P6: 0 | Q6: 0 | R6: 18943.218 | S6: 0 | T6: 0 | U6: =SUM(P6:T6) -> 18943.218 | V6: =O6-U6 -> -18943.218 | W6: 0 | X6: 0 | Y6: 0
A7: P360020 | B7: BOREAL | C7: 100 | D7: 高效一 | E7: 360 | F7: Google Inc. | G7: 44226 | H7: 42620 | I7: 2631434.3 | J7: 1817343 | K7: 0 | L7: 23329.8 | M7: 0 | N7: 0 | O7: =SUM(J7:N7) -> 1840672.8 | P7: 2104704 | Q7: 0 | R7: 0 | S7: 0 | T7: 10620.57 | U7: =SUM(P7:T7) -> 2115324.6 | V7: =O7-U7 -> -274651.77 | W7: 0 | X7: -5131.68 | Y7: -5131.68
A8: P250064 | B8: CZ460 | C8: 100 | D8: 高效一 | E8: 250 | F8: Western Digital Technologies,I | G8: 44226 | H8: 43566 | I8: 0 | J8: 0 | K8: 0 | L8: 0 | M8: 0 | N8: 0 | O8: =SUM(J8:N8) -> 0 | P8: 0 | Q8: 0 | R8: 0 | S8: 0 | T8: 0 | U8: =SUM(P8:T8) -> 0 | V8: =O8-U8 -> 0 | W8: 0 | X8: 288.39 | Y8: 288.39
A9: P330021 | B9: ASTRA | C9: 100 | D9: 高效一 | E9: 330 | F9: GN Audio A/S(GSC) | G9: 44226 | H9: 42328 | I9: 13469900 | J9: 13059715 | K9: 0 | L9: 831090.09 | M9: 0 | N9: 0 | O9: =SUM(J9:N9) -> 13890805 | P9: 12779048 | Q9: 0 | R9: 36326.51 | S9: 2166.36 | T9: 117492.9 | U9: =SUM(P9:T9) -> 12935034 | V9: =O9-U9 -> 955771.08 | W9: 75511.66 | X9: 66706.02 | Y9: 142217.68
A10: P268033 | B10: C77/C65/A131/A136 | C10: 100 | D10: 高效一 | E10: C268 | F10: Apple Inc. | G10: 44226 | H10: 44012 | I10: 0 | J10: 0 | K10: 0 | L10: 0 | M10: 0 | N10: 0 | O10: =SUM(J10:N10) -> 0 | P10: 0 | Q10: 0 | R10: 0 | S10: 1830.56 | T10: 0 | U10: =SUM(P10:T10) -> 1830.56 | V10: =O10-U10 -> -1830.56 | W10: 0 | X10: 0 | Y10: 0
A11: P208001 | B11: 韶音 | C11: 100 | D11: 高效一 | E11: C208 | F11: 深圳市韶音科技有限公司 | G11: 44226 | H11: 44004 | I11: 0 | J11: 19583.84 | K11: 0 | L11: 0 | M11: 0 | N11: 0 | O11: =SUM(J11:N11) -> 19583.84 | P11: 18359.86 | Q11: 0 | R11: 0 | S11: 0 | T11: 0 | U11: =SUM(P11:T11) -> 18359.86 | V11: =O11-U11 -> 1223.98 | W11: 0 | X11: 0 | Y11: 0
A12: P330010 | B12: Spiderman | C12: 100 | D12: 高效一 | E12: 330 | F12: GN Audio A/S(GSC) | G12: 44226 | H12: 44180 | I12: 8800 | J12: 252704.4 | K12: 0 | L12: 0 | M12: 0 | N12: 0 | O12: =SUM(J12:N12) -> 252704.4 | P12: 286413.71 | Q12: 0 | R12: 28705.24 | S12: 0 | T12: 3119.09 | U12: =SUM(P12:T12) -> 318238.04 | V12: =O12-U12 -> -65533.64 | W12: 0 | X12: 1168.45 | Y12: 1168.45
A13: P862001 | B13: PSC56一体机 | C13: 100 | D13: 高效一 | E13: C862 | F13: 影石创新科技股份有限公司 | G13: 44606 | I13: 1670294 | J13: 0 | K13: 0 | L13: 14864.56 | M13: 0 | N13: 0 | O13: =SUM(J13:N13) -> 14864.56 | P13: 0 | Q13: 0 | R13: 0 | S13: 41030.21 | T13: 35767.54 | U13: =SUM(P13:T13) -> 76797.75 | V13: =O13-U13 -> -61933.19 | W13: 0 | X13: 0 | Y13: 0
A14: P208002 | B14: SE | C14: 100 | D14: 高效一 | E14: C208 | F14: 深圳市韶音科技有限公司 | G14: 44226 | H14: 43888 | I14: 444114 | J14: 122071.52 | K14: 0 | L14: 815.8 | M14: 0 | N14: 0 | O14: =SUM(J14:N14) -> 122887.32 | P14: 143033.29 | Q14: 0 | R14: 9643.58 | S14: 3263.86 | T14: 35686.13 | U14: =SUM(P14:T14) -> 191626.86 | V14: =O14-U14 -> -68739.54 | W14: 0 | X14: 722.98 | Y14: 722.98
A15: P330043 | B15: STELLA | C15: 100 | D15: 高效一 | E15: 330 | F15: GN Audio A/S(GSC) | G15: 44662 | I15: 220000 | J15: 258814.08 | K15: 0 | L15: 0 | M15: 27561.6 | N15: 0 | O15: =SUM(J15:N15) -> 286375.68 | P15: 206623.2 | Q15: 0 | R15: 0 | S15: 0 | T15: 6191.12 | U15: =SUM(P15:T15) -> 212814.32 | V15: =O15-U15 -> 73561.36 | W15: 0 | X15: 0 | Y15: 0
A16: P330014 | B16: YOSHI | C16: 100 | D16: 高效一 | E16: 330 | F16: GN Audio A/S(GSC) | G16: 44226 | H16: 43969 | I16: 0 | J16: 0 | K16: 0 | L16: 0 | M16: 0 | N16: 0 | O16: =SUM(J16:N16) -> 0 | P16: 0 | Q16: 0 | R16: 76680.39 | S16: 0 | T16: 0 | U16: =SUM(P16:T16) -> 76680.39 | V16: =O16-U16 -> -76680.39 | W16: 0 | X16: 596.31 | Y16: 596.31
A17: P330036 | B17: COBRANDING-SPIDERMAN | C17: 100 | D17: 高效一 | E17: 330 | F17: GN Audio A/S(GSC) | G17: 44271 | H17: 42431 | I17: 257400 | J17: 0 | K17: 0 | L17: 0 | M17: 0 | N17: 0 | O17: =SUM(J17:N17) -> 0 | P17: 0 | Q17: 0 | R17: 0 | S17: 0 | T17: 0 | U17: =SUM(P17:T17) -> 0 | V17: =O17-U17 -> 0 | W17: 2860.31 | X17: 0 | Y17: 2860.31
A18: P208004 | B18: TT0 | C18: 100 | D18: 高效一 | E18: C208 | F18: 深圳市韶音科技有限公司 | G18: 44306 | H18: 44403 | I18: 1058000 | J18: 0 | K18: 0 | L18: 58861.71 | M18: 6497.93 | N18: 0 | O18: =SUM(J18:N18) -> 65359.64 | P18: 0 | Q18: 0 | R18: 0 | S18: 4207.97 | T18: 18480.02 | U18: =SUM(P18:T18) -> 22687.99 | V18: =O18-U18 -> 42671.65 | W18: 9564.21 | X18: 0 | Y18: 9564.21
A19: P208008 | B19: PARIS | C19: 100 | D19: 高效一 | E19: C208 | F19: 深圳市韶音科技有限公司 | G19: 44628 | I19: 765000 | J19: 0 | K19: 0 | L19: 2964.44 | M19: 0 | N19: 0 | O19: =SUM(J19:N19) -> 2964.44 | P19: 3127.06 | Q19: 0 | R19: 0 | S19: 56258.79 | T19: 53169.69 | U19: =SUM(P19:T19) -> 112555.54 | V19: =O19-U19 -> -109591.1 | W19: 0 | X19: 0 | Y19: 0
A20: P826001 | B20: BH72 | C20: 100 | D20: 高效一 | E20: C826 | F20: 厦门亿联网络技术股份有限公司 | G20: 44226 | H20: 44151 | I20: 0 | J20: 437209.3 | K20: 0 | L20: 0 | M20: 0 | N20: 0 | O20: =SUM(J20:N20) -> 437209.3 | P20: 644308.44 | Q20: 0 | R20: 11030.22 | S20: 0 | T20: 0 | U20: =SUM(P20:T20) -> 655338.66 | V20: =O20-U20 -> -218129.36 | W20: 0 | X20: 196.38 | Y20: 196.38
A21: P860001 | B21: HERCULES | C21: 100 | D21: 高效一 | E21: C860 | F21: 通力科技股份有限公司 | G21: 44546 | I21: 1147800 | J21: 580419.58 | K21: 0 | L21: 115844.7 | M21: 98452.38 | N21: 0 | O21: =SUM(J21:N21) -> 794716.66 | P21: 524475.53 | Q21: 0 | R21: 0 | S21: 8599.22 | T21: 71119.36 | U21: =SUM(P21:T21) -> 604194.11 | V21: =O21-U21 -> 190522.55 | W21: 9826.57 | X21: 0 | Y21: 9826.57
A22: P268029 | B22: FH001 | C22: 100 | D22: 高效一 | E22: C268 | F22: Apple Inc. | G22: 44226 | H22: 43357 | I22: 0 | J22: 0 | K22: 0 | L22: 0 | M22: 0 | N22: 1010070 | O22: =SUM(J22:N22) -> 1010070 | P22: 0 | Q22: 0 | R22: 0 | S22: 0 | T22: 0 | U22: =SUM(P22:T22) -> 0 | V22: =O22-U22 -> 1010070 | W22: 0 | X22: 0 | Y22: 0
A23: P291002 | B23: Dummy ED | C23: 100 | D23: 高效一 | E23: 291 | F23: Phonak AG | G23: 44226 | I23: 0 | J23: 0 | K23: 0 | L23: 0 | M23: 0 | N23: 0 | O23: =SUM(J23:N23) -> 0 | P23: 7347.6 | Q23: 0 | R23: 0 | S23: 0 | T23: 0 | U23: =SUM(P23:T23) -> 7347.6 | V23: =O23-U23 -> -7347.6 | W23: 0 | X23: 197.32 | Y23: 197.32
A24: P831001 | B24: PANDORA | C24: 100 | D24: 高效一 | E24: C831 | F24: August Home, Inc. | G24: 44264 | H24: 44288 | I24: 1922753.8 | J24: 245047.04 | K24: 0 | L24: 173982.87 | M24: 0 | N24: 0 | O24: =SUM(J24:N24) -> 419029.91 | P24: 209171.2 | Q24: 0 | R24: 0 | S24: 3787 | T24: 39859.64 | U24: =SUM(P24:T24) -> 252817.84 | V24: =O24-U24 -> 166212.07 | W24: 0 | X24: 0 | Y24: 0
A25: P268043 | B25: E23 | C25: 100 | D25: 高效一 | E25: C268 | F25: Apple Inc. | G25: 44543 | I25: 0 | J25: 0 | K25: 0 | L25: 0 | M25: 0 | N25: 0 | O25: =SUM(J25:N25) -> 0 | P25: 0 | Q25: 0 | R25: 0 | S25: 636.9 | T25: 0 | U25: =SUM(P25:T25) -> 636.9 | V25: =O25-U25 -> -636.9 | W25: 0 | X25: 0 | Y25: 0
A26: P268044 | B26: HP030 | C26: 100 | D26: 高效一 | E26: C268 | F26: Apple Inc. | G26: 44553 | I26: 15000 | J26: 0 | K26: 0 | L26: 0 | M26: 0 | N26: 0 | O26: =SUM(J26:N26) -> 0 | P26: 0 | Q26: 0 | R26: 0 | S26: 710.56 | T26: 13525.1 | U26: =SUM(P26:T26) -> 14235.66 | V26: =O26-U26 -> -14235.66 | W26: 0 | X26: 0 | Y26: 0
A27: P208007 | B27: WHARF左右耳挂 | C27: 100 | D27: 高效一 | E27: C208 | F27: 深圳市韶音科技有限公司 | G27: 44613 | I27: 242000 | J27: 0 | K27: 0 | L27: 4351.2 | M27: 0 | N27: 0 | O27: =SUM(J27:N27) -> 4351.2 | P27: 0 | Q27: 0 | R27: 0 | S27: 2001.7 | T27: 839.59 | U27: =SUM(P27:T27) -> 2841.29 | V27: =O27-U27 -> 1509.91 | W27: 0 | X27: 0 | Y27: 0
A28: P268042 | B28: A139 BOOT | C28: 100 | D28: 高效一 | E28: C268 | F28: Apple Inc. | G28: 44441 | I28: 20000 | J28: 0 | K28: 0 | L28: 0 | M28: 0 | N28: 0 | O28: =SUM(J28:N28) -> 0 | P28: 0 | Q28: 0 | R28: 0 | S28: -6032.23 | T28: 0 | U28: =SUM(P28:T28) -> -6032.23 | V28: =O28-U28 -> 6032.23 | W28: 0 | X28: 0 | Y28: 0
A29: P831003 | B29: NEST 1.5 | C29: 100 | D29: 高效一 | E29: C831 | F29: August Home, Inc. | G29: 44411 | I29: 1561780 | J29: 0 | K29: 0 | L29: 9971.2 | M29: 0 | N29: 0 | O29: =SUM(J29:N29) -> 9971.2 | P29: 0 | Q29: 0 | R29: 0 | S29: 0 | T29: 0 | U29: =SUM(P29:T29) -> 0 | V29: =O29-U29 -> 9971.2 | W29: 0 | X29: 0 | Y29: 0
A30: P330038 | B30: MAPLE | C30: 100 | D30: 高效一 | E30: 330 | F30: GN Audio A/S(GSC) | G30: 44307 | H30: 42198 | I30: 1122000 | J30: 0 | K30: 0 | L30: 48546 | M30: 0 | N30: 0 | O30: =SUM(J30:N30) -> 48546 | P30: 0 | Q30: 0 | R30: 0 | S30: 0 | T30: 0 | U30: =SUM(P30:T30) -> 0 | V30: =O30-U30 -> 48546 | W30: 0 | X30: 0 | Y30: 0
A31: P460009 | B31: CORAL | C31: 601 | D31: 高效二 | E31: 460 | F31: Amazon com, Inc | G31: 44226 | H31: 44382 | I31: 4349725.9 | J31: 0 | K31: 0 | L31: 0 | M31: 0 | N31: 0 | O31: =SUM(J31:N31) -> 0 | P31: 0 | Q31: 0 | R31: 279883.9 | S31: 56841.87 | T31: 1965.14 | U31: =SUM(P31:T31) -> 338690.91 | V31: =O31-U31 -> -338690.91 | W31: 9846.29 | X31: 30890.11 | Y31: 40736.4
A32: P460012 | B32: MARLIN | C32: 601 | D32: 高效二 | E32: 460 | F32: Amazon com, Inc | G32: 44431 | H32: 44770 | I32: 3950325.7 | J32: 2091712 | K32: 0 | L32: 224672.23 | M32: 223661.42 | N32: 15862.48 | O32: =SUM(J32:N32) -> 2555908.1 | P32: 2469521.6 | Q32: 0 | R32: 8595.57 | S32: 69525.97 | T32: 136589.39 | U32: =SUM(P32:T32) -> 2684232.5 | V32: =O32-U32 -> -128324.4 | W32: 40703.51 | X32: 29357.25 | Y32: 70060.76
A33: P460004 | B33: POWELL | C33: 601 | D33: 高效二 | E33: 460 | F33: Amazon com, Inc | G33: 44226 | H33: 44410 | I33: 0 | J33: 0 | K33: 0 | L33: 0 | M33: 0 | N33: 0 | O33: =SUM(J33:N33) -> 0 | P33: 0 | Q33: 0 | R33: 4380.2 | S33: 0 | T33: 11170.63 | U33: =SUM(P33:T33) -> 15550.83 | V33: =O33-U33 -> -15550.83 | W33: 0 | X33: 30935.73 | Y33: 30935.73
A34: P460003 | B34: SPRINKLE | C34: 601 | D34: 高效二 | E34: 460 | F34: Amazon com, Inc | G34: 44226 | H34: 43620 | I34: 0 | J34: 0 | K34: 0 | L34: 0 | M34: 0 | N34: 0 | O34: =SUM(J34:N34) -> 0 | P34: 0 | Q34: 0 | R34: 0 | S34: 0 | T34: 0 | U34: =SUM(P34:T34) -> 0 | V34: =O34-U34 -> 0 | W34: 2167.1 | X34: 2165.99 | Y34: 4333.09
A35: P821002 | B35: S3 | C35: 601 | D35: 高效二 | E35: C821 | F35: Square Inc. | G35: 44226 | H35: 44133 | I35: 0 | J35: 0 | K35: 0 | L35: 141849.65 | M35: 0 | N35: 0 | O35: =SUM(J35:N35) -> 141849.65 | P35: 0 | Q35: 0 | R35: 163503.19 | S35: 19644.78 | T35: 51621.69 | U35: =SUM(P35:T35) -> 234769.66 | V35: =O35-U35 -> -92920.01 | W35: 56824.8 | X35: 29225.11 | Y35: 86049.91
A36: P460002 | B36: Project Vesta | C36: 601 | D36: 高效二 | E36: 460 | F36: Amazon com, Inc | G36: 44226 | H36: 44407 | I36: 0 | J36: 0 | K36: 0 | L36: 38291.88 | M36: 0 | N36: 0 | O36: =SUM(J36:N36) -> 38291.88 | P36: 0 | Q36: 0 | R36: 26496.05 | S36: 0 | T36: 4594.01 | U36: =SUM(P36:T36) -> 31090.06 | V36: =O36-U36 -> 7201.82 | W36: 16231.55 | X36: 20458.34 | Y36: 36689.89
A37: P460011 | B37: CRUSH | C37: 601 | D37: 高效二 | E37: 460 | F37: Amazon com, Inc | G37: 44350 | H37: 44369 | I37: 3460402 | J37: 3396616 | K37: 0 | L37: 34473.85 | M37: 9684.4 | N37: 0 | O37: =SUM(J37:N37) -> 3440774.2 | P37: 4062531.8 | Q37: 0 | R37: 1558.56 | S37: 31301.64 | T37: 30471.27 | U37: =SUM(P37:T37) -> 4125863.3 | V37: =O37-U37 -> -685089.02 | W37: 3820.94 | X37: 9481.93 | Y37: 13302.87
A38: P821003 | B38: S3 MOUNT | C38: 601 | D38: 高效二 | E38: C821 | F38: Square Inc. | G38: 44480 | I38: 2180000 | J38: 0 | K38: 0 | L38: 0 | M38: 0 | N38: 513162.54 | O38: =SUM(J38:N38) -> 513162.54 | P38: 0 | Q38: 0 | R38: 0 | S38: 28218.91 | T38: 113723.7 | U38: =SUM(P38:T38) -> 141942.61 | V38: =O38-U38 -> 371219.93 | W38: 11345.58 | X38: 2043.05 | Y38: 13388.63
A39: P268032 | B39: HP025 | C39: 601 | D39: 高效二 | E39: C268 | F39: Apple Inc. | G39: 44226 | H39: 43632 | I39: 0 | J39: 0 | K39: 0 | L39: 0 | M39: 0 | N39: -310315.19 | O39: =SUM(J39:N39) -> -310315.19 | P39: 0 | Q39: 0 | R39: 0 | S39: 0 | T39: 0 | U39: =SUM(P39:T39) -> 0 | V39: =O39-U39 -> -310315.19 | W39: 4453.91 | X39: 360784.34 | Y39: 365238.25
A40: P460005 | B40: THEIA | C40: 601 | D40: 高效二 | E40: 460 | F40: Amazon com, Inc | G40: 44226 | H40: 44127 | I40: 0 | J40: 0 | K40: 0 | L40: 0 | M40: 0 | N40: 0 | O40: =SUM(J40:N40) -> 0 | P40: 4103.17 | Q40: 0 | R40: 27904.43 | S40: 1095.25 | T40: 0 | U40: =SUM(P40:T40) -> 33102.85 | V40: =O40-U40 -> -33102.85 | W40: 1990.51 | X40: 42787.96 | Y40: 44778.47
...

Sheet HP1
A1: HP1 2024年1-6月NPI明细
A2: 币别:HKD
A3: TK项目号 | B3: 项目名称 | C3: 利润中心 | D3: 事业部 | E3: 终端客户 | F3: 终端客户名称 | G3: 创建日期 | H3: 量产日期 | I3: NPI预算收入 | J3: 注塑模具收入 | K3: 其他模具收入 | L3: 样板费收入 | M3: 夹治具收入 | N3: 其它杂项收入 | O3: 量产前收入 | P3: 注塑模具成本 | Q3: 其他模具成本 | R3: 自费模具摊销 | S3: 量产前夹治具成本 | T3: 试模成本 | U3: 量产前成本 | V3: 量产前收益 | W3: 量产后夹治具成本 | X3: 量产后打样成本 | Y3: 量产后成本 | Z3: 项目收益
A4: P208001 | B4: 韶音 | C4: 100 | D4: 高效一 | E4: C208 | F4: 深圳市韶音科技有限公司 | G4: 44226 | H4: 44004 | I4: 0 | J4: 0 | K4: 0 | L4: 36330.73 | M4: 0 | N4: 0 | O4: 36330.73 | P4: 0 | Q4: 0 | R4: 2984.41 | S4: 0 | T4: 0 | U4: 2984.41 | V4: 33346.32 | W4: 0 | X4: 0 | Y4: 0 | Z4: =V4-Y4 -> 33346.32
A5: P208002 | B5: SE | C5: 100 | D5: 高效一 | E5: C208 | F5: 深圳市韶音科技有限公司 | G5: 44226 | H5: 43888 | I5: 2664684 | J5: 9708.74 | K5: 0 | L5: 0 | M5: 0 | N5: 0 | O5: 9708.74 | P5: 0 | Q5: 0 | R5: 2355.01 | S5: 0 | T5: 0 | U5: 2355.01 | V5: 7353.73 | W5: 0 | X5: 68.2 | Y5: 68.2 | Z5: =V5-Y5 -> 7285.53
A6: P208003 | B6: VIE | C6: 100 | D6: 高效一 | E6: C208 | F6: 深圳市韶音科技有限公司 | G6: 44226 | H6: 44223 | I6: 9839800 | J6: 40021.57 | K6: 0 | L6: 0 | M6: 0 | N6: 0 | O6: 40021.57 | P6: 31503.28 | Q6: 0 | R6: 21366.23 | S6: 0 | T6: 0 | U6: 52869.51 | V6: -12847.94 | W6: 0 | X6: 41912.38 | Y6: 41912.38 | Z6: =V6-Y6 -> -54760.32
A7: P208004 | B7: TT0 | C7: 100 | D7: 高效一 | E7: C208 | F7: 深圳市韶音科技有限公司 | G7: 44306 | H7: 44403 | I7: 1058000 | J7: 0 | K7: 0 | L7: -3.24 | M7: 0 | N7: 0 | O7: -3.24 | P7: 0 | Q7: 0 | R7: 0 | S7: 0 | T7: 0 | U7: 0 | V7: -3.24 | W7: 0 | X7: 0 | Y7: 0 | Z7: =V7-Y7 -> -3.24
A8: P208008 | B8: PARIS | C8: 100 | D8: 高效一 | E8: C208 | F8: 深圳市韶音科技有限公司 | G8: 44628 | I8: 3825000 | J8: 7055.03 | K8: 0 | L8: 0 | M8: 0 | N8: 0 | O8: 7055.03 | P8: 0 | Q8: 0 | R8: 5660.3 | S8: 0 | T8: 0 | U8: 5660.3 | V8: 1394.73 | W8: 0 | X8: 275.41 | Y8: 275.41 | Z8: =V8-Y8 -> 1119.32
A9: P208009 | B9: HSD | C9: 100 | D9: 高效一 | E9: C208 | F9: 深圳市韶音科技有限公司 | G9: 44799 | I9: 2874000 | J9: 4314.99 | K9: 0 | L9: -1441.24 | M9: 0 | N9: 0 | O9: 2873.75 | P9: 0 | Q9: 0 | R9: 7318.74 | S9: 0 | T9: 0 | U9: 7318.74 | V9: -4444.99 | W9: 0 | X9: 395.44 | Y9: 395.44 | Z9: =V9-Y9 -> -4840.43
A10: P208010 | B10: CWS | C10: 100 | D10: 高效一 | E10: C208 | F10: 深圳市韶音科技有限公司 | G10: 44883 | I10: 18946800 | J10: 194150.34 | K10: 0 | L10: -62091.47 | M10: 0 | N10: 0 | O10: 132058.87 | P10: 206267.3 | Q10: 0 | R10: 87427.72 | S10: 477.32 | T10: 0 | U10: 294172.34 | V10: -162113.47 | W10: 0 | X10: 25997.1 | Y10: 25997.1 | Z10: =V10-Y10 -> -188110.57
A11: P330010 | B11: Spiderman | C11: 100 | D11: 高效一 | E11: 330 | F11: GN Audio A/S(GSC) | G11: 44226 | H11: 44180 | I11: 94000 | J11: 0 | K11: 0 | L11: 0 | M11: 0 | N11: 0 | O11: 0 | P11: 0 | Q11: 0 | R11: 1267.94 | S11: 0 | T11: 0 | U11: 1267.94 | V11: -1267.94 | W11: 0 | X11: 0 | Y11: 0 | Z11: =V11-Y11 -> -1267.94
A12: P330014 | B12: YOSHI | C12: 100 | D12: 高效一 | E12: 330 | F12: GN Audio A/S(GSC) | G12: 44226 | H12: 43969 | I12: 0 | J12: 0 | K12: 0 | L12: 0 | M12: 0 | N12: 0 | O12: 0 | P12: 0 | Q12: 0 | R12: 0 | S12: 0 | T12: 0 | U12: 0 | V12: 0 | W12: 0 | X12: 0 | Y12: 0 | Z12: =V12-Y12 -> 0
A13: P330021 | B13: ASTRA | C13: 100 | D13: 高效一 | E13: 330 | F13: GN Audio A/S(GSC) | G13: 44226 | H13: 42328 | I13: 80819400 | J13: 0 | K13: 0 | L13: 0 | M13: 0 | N13: 0 | O13: 0 | P13: 0 | Q13: 0 | R13: 2344.7 | S13: 27211.28 | T13: 0 | U13: 29555.98 | V13: -29555.98 | W13: 0 | X13: 0 | Y13: 0 | Z13: =V13-Y13 -> -29555.98
A14: P330036 | B14: COBRANDING-SPIDERMAN | C14: 100 | D14: 高效一 | E14: 330 | F14: GN Audio A/S(GSC) | G14: 44271 | H14: 42431 | I14: 0 | J14: 0 | K14: 0 | L14: 0 | M14: 0 | N14: 0 | O14: 0 | P14: 0 | Q14: 0 | R14: 0 | S14: 0 | T14: 0 | U14: 0 | V14: 0 | W14: 0 | X14: 0 | Y14: 0 | Z14: =V14-Y14 -> 0
A15: P330041 | B15: WILLOW | C15: 100 | D15: 高效一 | E15: 330 | F15: GN Audio A/S(GSC) | G15: 44487 | H15: 44928 | I15: 50367000 | J15: 43635.9 | K15: 0 | L15: 0 | M15: 0 | N15: 0 | O15: 43635.9 | P15: 42091.21 | Q15: 0 | R15: 21652.58 | S15: 20047.54 | T15: 0 | U15: 83791.33 | V15: -40155.43 | W15: 0 | X15: 2116.79 | Y15: 2116.79 | Z15: =V15-Y15 -> -42272.22
A16: P360020 | B16: BOREAL | C16: 100 | D16: 高效一 | E16: 360 | F16: Google Inc. | G16: 44226 | H16: 42620 | I16: 0 | J16: 0 | K16: 0 | L16: 0 | M16: 0 | N16: 0 | O16: 0 | P16: 0 | Q16: 0 | R16: 0 | S16: 0 | T16: 0 | U16: 0 | V16: 0 | W16: 0 | X16: 0 | Y16: 0 | Z16: =V16-Y16 -> 0
A17: P435004 | B17: Dublin MONO | C17: 100 | D17: 高效一 | E17: 330 | F17: GN Audio A/S(GSC) | G17: 44226 | H17: 42181 | I17: 0 | J17: 1926748.6 | K17: 0 | L17: 0 | M17: 0 | N17: 0 | O17: 1926748.6 | P17: 1138252 | Q17: 0 | R17: 25728.59 | S17: 41557.25 | T17: 0 | U17: 1205537.8 | V17: 721210.76 | W17: 0 | X17: 2192 | Y17: 2192 | Z17: =V17-Y17 -> 719018.76
A18: P831001 | B18: PANDORA | C18: 100 | D18: 高效一 | E18: C831 | F18: August Home, Inc. | G18: 44264 | H18: 44288 | I18: 11536523 | J18: 0 | K18: 0 | L18: 2755.7 | M18: 0 | N18: 0 | O18: 2755.7 | P18: 0 | Q18: 0 | R18: 6022.62 | S18: 6587.04 | T18: 0 | U18: 12609.66 | V18: -9853.96 | W18: 0 | X18: 17481.01 | Y18: 17481.01 | Z18: =V18-Y18 -> -27334.97
A19: P860005 | B19: PELICAN | C19: 100 | D19: 高效一 | E19: C860 | F19: 通力科技股份有限公司 | G19: 44818 | I19: 6430600 | J19: 32327.59 | K19: 0 | L19: 0 | M19: 0 | N19: 0 | O19: 32327.59 | P19: 60665.25 | Q19: 0 | R19: 35172.61 | S19: 4773.22 | T19: 31671.48 | U19: 132282.56 | V19: -99954.97 | W19: 0 | X19: 3581.82 | Y19: 3581.82 | Z19: =V19-Y19 -> -103536.79
A20: P862001 | B20: PSC56一体机 | C20: 100 | D20: 高效一 | E20: C862 | F20: 影石创新科技股份有限公司 | G20: 44606 | I20: 10261764 | J20: 71780.15 | K20: 0 | L20: 2357.61 | M20: 0 | N20: 0 | O20: 74137.76 | P20: 14455.23 | Q20: 0 | R20: 10491.48 | S20: 19378.5 | T20: 0 | U20: 44325.21 | V20: 29812.55 | W20: 0 | X20: 0 | Y20: 0 | Z20: =V20-Y20 -> 29812.55
A21: P862002 | B21: IAC2 | C21: 100 | D21: 高效一 | E21: C862 | F21: 影石创新科技股份有限公司 | G21: 44776 | I21: 7687368 | J21: 1116823.7 | K21: 0 | L21: 449.11 | M21: 0 | N21: 0 | O21: 1117272.8 | P21: 1275993.2 | Q21: 0 | R21: 8878.75 | S21: 0 | T21: 549.65 | U21: 1285421.6 | V21: -168148.78 | W21: 0 | X21: 11459.88 | Y21: 11459.88 | Z21: =V21-Y21 -> -179608.66
A22: P869003 | B22: FI05 | C22: 100 | D22: 高效一 | E22: C869 | F22: 深圳市爱立康医疗股份有限公司 | G22: 44825 | I22: 1059000 | J22: 248207.23 | K22: 0 | L22: 0 | M22: 0 | N22: 2863.94 | O22: 251071.17 | P22: 401510.24 | Q22: 0 | R22: 493.89 | S22: 0 | T22: -487.47 | U22: 401516.66 | V22: -150445.49 | W22: 0 | X22: 0 | Y22: 0 | Z22: =V22-Y22 -> -150445.49
A23: P884001 | B23: GFD | C23: 100 | D23: 高效一 | E23: C884 | F23: Glowforge,Inc. | G23: 44931 | I23: 3574500 | J23: 0 | K23: 0 | L23: 4084.5 | M23: 0 | N23: 0 | O23: 4084.5 | P23: 0 | Q23: 0 | R23: 3038.72 | S23: 0 | T23: 0 | U23: 3038.72 | V23: 1045.78 | W23: 0 | X23: 0 | Y23: 0 | Z23: =V23-Y23 -> 1045.78
A24: P869001 | B24: FI02 | C24: 100 | D24: 高效一 | E24: C869 | F24: 深圳市爱立康医疗股份有限公司 | G24: 44777 | I24: 214700 | J24: 0 | K24: 0 | L24: 0 | M24: 0 | N24: 0 | O24: 0 | P24: 0 | Q24: 0 | R24: 0 | S24: 0 | T24: 0 | U24: 0 | V24: 0 | W24: 0 | X24: 0 | Y24: 0 | Z24: =V24-Y24 -> 0
A25: P330044 | B25: ELFIN | C25: 100 | D25: 高效一 | E25: 330 | F25: GN Audio A/S(GSC) | G25: 44973 | I25: 44000 | J25: 0 | K25: 0 | L25: 0 | M25: 0 | N25: 0 | O25: 0 | P25: 0 | Q25: 0 | R25: 0 | S25: 0 | T25: 0 | U25: 0 | V25: 0 | W25: 0 | X25: 0 | Y25: 0 | Z25: =V25-Y25 -> 0
A26: P208007 | B26: WHARF左右耳挂 | C26: 100 | D26: 高效一 | E26: C208 | F26: 深圳市韶音科技有限公司 | G26: 44613 | I26: 242000 | J26: 0 | K26: 0 | L26: 0 | M26: 0 | N26: 0 | O26: 0 | P26: 0 | Q26: 0 | R26: 0 | S26: 0 | T26: -527.39 | U26: -527.39 | V26: 527.39 | W26: 0 | X26: 0 | Y26: 0 | Z26: =V26-Y26 -> 527.39
A27: P208011 | B27: HUGO | C27: 100 | D27: 高效一 | E27: C208 | F27: 深圳市韶音科技有限公司 | G27: 44971 | I27: 212600 | J27: 245709.88 | K27: 0 | L27: -38.13 | M27: 0 | N27: 0 | O27: 245671.75 | P27: 217391.3 | Q27: 0 | R27: 0 | S27: 0 | T27: 0 | U27: 217391.3 | V27: 28280.45 | W27: 0 | X27: 0 | Y27: 0 | Z27: =V27-Y27 -> 28280.45
A28: P330020 | B28: Leo | C28: 100 | D28: 高效一 | E28: 330 | F28: GN Audio A/S(GSC) | G28: 44226 | H28: 44371 | I28: 0 | J28: 0 | K28: 0 | L28: 0 | M28: 0 | N28: 0 | O28: 0 | P28: 0 | Q28: 0 | R28: 0 | S28: 0 | T28: -11074.03 | U28: -11074.03 | V28: 11074.03 | W28: 0 | X28: 0 | Y28: 0 | Z28: =V28-Y28 -> 11074.03
A29: P860006 | B29: TM04 | C29: 100 | D29: 高效一 | E29: C860 | F29: 通力科技股份有限公司 | G29: 44977 | I29: 222200 | J29: 153985.87 | K29: 0 | L29: 0 | M29: 0 | N29: 0 | O29: 153985.87 | P29: 0 | Q29: 0 | R29: 0 | S29: 0 | T29: 0 | U29: 0 | V29: 153985.87 | W29: 0 | X29: 0 | Y29: 0 | Z29: =V29-Y29 -> 153985.87
A30: P860008 | B30: SONY HDX2981 | C30: 100 | D30: 高效一 | E30: C860 | F30: 通力科技股份有限公司 | G30: 45049 | I30: 2457000 | J30: 2419782.6 | K30: 0 | L30: 25587.07 | M30: 0 | N30: 0 | O30: 2445369.7 | P30: 3999366.5 | Q30: 0 | R30: 8283.06 | S30: -58335.24 | T30: 149873.15 | U30: 4099187.5 | V30: -1653817.8 | W30: 0 | X30: 20725.47 | Y30: 20725.47 | Z30: =V30-Y30 -> -1674543.3
A31: P330008 | B31: Binary HB | C31: 100 | D31: 高效一 | E31: 330 | F31: GN Audio A/S(GSC) | G31: 44226 | H31: 43266 | I31: 0 | J31: 0 | K31: 0 | L31: 0 | M31: 0 | N31: 0 | O31: 0 | P31: 0 | Q31: 0 | R31: 2445.26 | S31: 0 | T31: 0 | U31: 2445.26 | V31: -2445.26 | W31: 0 | X31: 0 | Y31: 0 | Z31: =V31-Y31 -> -2445.26
A32: P831003 | B32: NEST 1.5 | C32: 100 | D32: 高效一 | E32: C831 | F32: August Home, Inc. | G32: 44411 | I32: 1611280 | J32: 0 | K32: 0 | L32: 0 | M32: 0 | N32: 0 | O32: 0 | P32: 0 | Q32: 0 | R32: 5750.9 | S32: 0 | T32: 0 | U32: 5750.9 | V32: -5750.9 | W32: 0 | X32: 0 | Y32: 0 | Z32: =V32-Y32 -> -5750.9
A33: P208005 | B33: MYLEZ | C33: 100 | D33: 高效一 | E33: C208 | F33: 深圳市韶音科技有限公司 | G33: 44526 | I33: 0 | J33: 0 | K33: 0 | L33: 0 | M33: 0 | N33: 0 | O33: 0 | P33: 0 | Q33: 0 | R33: 0 | S33: 0 | T33: 0 | U33: 0 | V33: 0 | W33: 0 | X33: 0 | Y33: 0 | Z33: =V33-Y33 -> 0
A34: P330047 | B34: ASTRA PRO | C34: 100 | D34: 高效一 | E34: 330 | F34: GN Audio A/S(GSC) | G34: 45145 | I34: 0 | J34: 54600 | K34: 0 | L34: 639.6 | M34: 0 | N34: 0 | O34: 55239.6 | P34: 51480 | Q34: 0 | R34: 0 | S34: 8878.21 | T34: 1243.98 | U34: 61602.19 | V34: -6362.59 | W34: 0 | X34: 4937.84 | Y34: 4937.84 | Z34: =V34-Y34 -> -11300.43
A35: P250064 | B35: CZ460 | C35: 100 | D35: 高效一 | E35: 250 | F35: Western Digital Technologies,I | G35: 44226 | H35: 43566 | I35: 0 | J35: 0 | K35: 0 | L35: 0 | M35: 0 | N35: 0 | O35: 0 | P35: 0 | Q35: 0 | R35: 0 | S35: 0 | T35: 0 | U35: 0 | V35: 0 | W35: 0 | X35: 0 | Y35: 0 | Z35: =V35-Y35 -> 0
A36: P370001 | B36: Wrist Worn | C36: 100 | D36: 高效一 | E36: 370 | F36: Ava AG | G36: 44226 | H36: 43630 | I36: 616000 | J36: 0 | K36: 0 | L36: 0 | M36: 0 | N36: 0 | O36: 0 | P36: 0 | Q36: 0 | R36: 0 | S36: 0 | T36: 0 | U36: 0 | V36: 0 | W36: 0 | X36: 0 | Y36: 0 | Z36: =V36-Y36 -> 0
A37: P250059 | B37: CZ57 | C37: 100 | D37: 高效一 | E37: 25001 | F37: Western Digital Technologies,Inc. | G37: 0 | H37: 0 | I37: 0 | J37: 0 | K37: 0 | L37: 0 | M37: 0 | N37: 0 | O37: 0 | P37: 0 | Q37: 0 | R37: 0 | S37: 0 | T37: 0 | U37: 0 | V37: 0 | W37: 0 | X37: 0 | Y37: 0 | Z37: =V37-Y37 -> 0
A38: P250063 | B38: Rugged | C38: 100 | D38: 高效一 | E38: 25011 | F38: Western Digital Technologies,Inc. | G38: 0 | H38: 0 | J38: 0 | K38: 0 | L38: 0 | M38: 0 | N38: 0 | O38: 0 | P38: 0 | Q38: 0 | R38: 0 | S38: 0 | T38: 0 | U38: 0 | V38: 0 | W38: 0 | X38: 0 | Y38: 0 | Z38: =V38-Y38 -> 0
A39: P360004 | B39: Gotham | C39: 100 | D39: 高效一 | E39: 360 | F39: Google Inc. | G39: 44226 | H39: 43761 | I39: 0 | J39: 0 | K39: 0 | L39: 0 | M39: 0 | N39: 0 | O39: 0 | P39: 0 | Q39: 0 | R39: 7221.44 | S39: 0 | T39: 0 | U39: 7221.44 | V39: -7221.44 | W39: 0 | X39: 0 | Y39: 0 | Z39: =V39-Y39 -> -7221.44
A40: P876001 | B40: BHP701 | C40: 100 | D40: 高效一 | E40: C876 | F40: Sonos, Inc. | G40: 44830 | I40: 13348000 | J40: 0 | K40: 0 | L40: 0 | M40: 0 | N40: 0 | O40: 0 | P40: 0 | Q40: 0 | R40: 0 | S40: 0 | T40: 0 | U40: 0 | V40: 0 | W40: 0 | X40: 0 | Y40: 0 | Z40: =V40-Y40 -> 0
...

Sheet HP2
A1: HP2 2024年1-2月NPI报表明细
A2: TK项目号 | B2: 项目名称 | C2: 利润中心 | D2: 事业部 | E2: 终端客户 | F2: 终端客户名称 | G2: 创建日期 | H2: 量产日期 | I2: NPI预算收入 | J2: 注塑模具收入 | K2: 其他模具收入 | L2: 样板费收入 | M2: 夹治具收入 | N2: 其它杂项收入 | O2: 量产前收入 | P2: 注塑模具成本 | Q2: 其他模具成本 | R2: 自费模具摊销 | S2: 量产前夹治具成本 | T2: 试模成本 | U2: 量产前成本 | V2: 量产前收益 | W2: 量产后夹治具成本 | X2: 量产后打样成本 | Y2: 量产后成本
A3: P293011 | B3: Jbay | C3: 601 | D3: 高效二 | E3: 293 | F3: GoPro, Inc. | G3: 44226 | H3: 43717 | I3: 0 | J3: 0 | K3: 0 | L3: 0 | M3: 0 | N3: 0 | O3: 0 | P3: 0 | Q3: 0 | R3: 0 | S3: 0 | T3: 0 | U3: 0 | V3: 0 | W3: 0 | X3: 0 | Y3: 0
A4: P460002 | B4: Project Vesta | C4: 601 | D4: 高效二 | E4: 460 | F4: Amazon com, Inc | G4: 44226 | H4: 44407 | I4: 0 | J4: 0 | K4: 0 | L4: 0 | M4: 0 | N4: 0 | O4: 0 | P4: 0 | Q4: 0 | R4: 0 | S4: 0 | T4: 0 | U4: 0 | V4: 0 | W4: 0 | X4: 0 | Y4: 0
A5: P460005 | B5: THEIA | C5: 601 | D5: 高效二 | E5: 460 | F5: Amazon com, Inc | G5: 44226 | H5: 44127 | I5: 0 | J5: 0 | K5: 0 | L5: 0 | M5: 0 | N5: 0 | O5: 0 | P5: 0 | Q5: 0 | R5: 0 | S5: 0 | T5: 0 | U5: 0 | V5: 0 | W5: 0 | X5: 0 | Y5: 0
A6: P460009 | B6: CORAL | C6: 601 | D6: 高效二 | E6: 460 | F6: Amazon com, Inc | G6: 44226 | H6: 44382 | I6: 0 | J6: 0 | K6: 0 | L6: 0 | M6: 0 | N6: 0 | O6: 0 | P6: 0 | Q6: 0 | R6: 0 | S6: 0 | T6: 0 | U6: 0 | V6: 0 | W6: 0 | X6: 0 | Y6: 0
A7: P460011 | B7: CRUSH | C7: 601 | D7: 高效二 | E7: 460 | F7: Amazon com, Inc | G7: 44350 | H7: 44369 | I7: 0 | J7: 0 | K7: 0 | L7: 0 | M7: 0 | N7: 0 | O7: 0 | P7: 0 | Q7: 0 | R7: 0 | S7: 0 | T7: 0 | U7: 0 | V7: 0 | W7: 0 | X7: 0 | Y7: 0
A8: P460012 | B8: MARLIN | C8: 601 | D8: 高效二 | E8: 460 | F8: Amazon com, Inc | G8: 44431 | H8: 44770 | I8: 0 | J8: 0 | K8: 0 | L8: 0 | M8: 0 | N8: 0 | O8: 0 | P8: 0 | Q8: 0 | R8: 0 | S8: 0 | T8: 0 | U8: 0 | V8: 0 | W8: 0 | X8: 0 | Y8: 0
A9: P460013 | B9: GERALD | C9: 601 | D9: 高效二 | E9: 460 | F9: Amazon com, Inc | G9: 44851 | I9: 7305383 | J9: 0 | K9: 0 | L9: 0 | M9: 0 | N9: 0 | O9: 0 | P9: 0 | Q9: 0 | R9: 0.02 | S9: 0 | T9: 0 | U9: 0.02 | V9: -0.02 | W9: 0 | X9: 0 | Y9: 0
A10: P460014 | B10: CITRINE | C10: 601 | D10: 高效二 | E10: 460 | F10: Amazon com, Inc | G10: 44872 | I10: 0 | J10: 0 | K10: 0 | L10: 0 | M10: 0 | N10: 0 | O10: 0 | P10: 0 | Q10: 0 | R10: 0 | S10: 0 | T10: 0 | U10: 0 | V10: 0 | W10: 0 | X10: 0 | Y10: 0
A11: P821002 | B11: S3 | C11: 601 | D11: 高效二 | E11: C821 | F11: Square Inc. | G11: 44226 | H11: 44133 | I11: 0 | J11: 0 | K11: 0 | L11: 0 | M11: 0 | N11: 0 | O11: 0 | P11: 0 | Q11: 0 | R11: 0 | S11: 0 | T11: 0 | U11: 0 | V11: 0 | W11: 0 | X11: 0 | Y11: 0
A12: P821003 | B12: S3 MOUNT | C12: 601 | D12: 高效二 | E12: C821 | F12: Square Inc. | G12: 44480 | I12: 0 | J12: 0 | K12: 0 | L12: 0 | M12: 0 | N12: 0 | O12: 0 | P12: 0 | Q12: 0 | R12: 0 | S12: 0 | T12: 0 | U12: 0 | V12: 0 | W12: 0 | X12: 0 | Y12: 0
A13: P821004 | B13: S3B | C13: 601 | D13: 高效二 | E13: C821 | F13: Square Inc. | G13: 44894 | I13: 0 | J13: 0 | K13: 0 | L13: 0 | M13: 0 | N13: 0 | O13: 0 | P13: 0 | Q13: 0 | R13: 0 | S13: 0 | T13: 0 | U13: 0 | V13: 0 | W13: 0 | X13: 0 | Y13: 0
A14: P831006 | B14: TITAN | C14: 601 | D14: 高效二 | E14: C831 | F14: August Home, Inc. | G14: 44770 | I14: 0 | J14: 0 | K14: 0 | L14: 0 | M14: 0 | N14: 0 | O14: 0 | P14: 0 | Q14: 0 | R14: 0 | S14: 0 | T14: 0 | U14: 0 | V14: 0 | W14: 0 | X14: 0 | Y14: 0
A15: P856001 | B15: NT02 | C15: 601 | D15: 高效二 | E15: C856 | F15: 微软(中国)有限公司 | G15: 44767 | I15: 0 | J15: 0 | K15: 0 | L15: 0 | M15: 0 | N15: 0 | O15: 0 | P15: 0 | Q15: 0 | R15: 0 | S15: 0 | T15: 0 | U15: 0 | V15: 0 | W15: 0 | X15: 0 | Y15: 0
A16: P860004 | B16: Q60 | C16: 601 | D16: 高效二 | E16: C860 | F16: 通力科技股份有限公司 | G16: 44784 | I16: 0 | J16: 0 | K16: 0 | L16: 0 | M16: 0 | N16: 0 | O16: 0 | P16: 0 | Q16: 0 | R16: 0 | S16: 0 | T16: 0 | U16: 0 | V16: 0 | W16: 0 | X16: 0 | Y16: 0
A17: P863001 | B17: WTH13 | C17: 601 | D17: 高效二 | E17: C863 | F17: Stripe Inc. | G17: 44628 | I17: 0 | J17: 0 | K17: 0 | L17: 0 | M17: 0 | N17: 0 | O17: 0 | P17: 0 | Q17: 0 | R17: 0 | S17: 0 | T17: 0 | U17: 0 | V17: 0 | W17: 0 | X17: 0 | Y17: 0
A18: P863002 | B18: M2 | C18: 601 | D18: 高效二 | E18: C863 | F18: Stripe Inc. | G18: 44775 | I18: 0 | J18: 0 | K18: 0 | L18: 0 | M18: 0 | N18: 0 | O18: 0 | P18: 0 | Q18: 0 | R18: 0 | S18: 0 | T18: 0 | U18: 0 | V18: 0 | W18: 0 | X18: 0 | Y18: 0
A19: P268002 | B19: B60 | C19: 601 | D19: 高效二 | E19: C268 | F19: Apple Inc. | G19: 44226 | H19: 42198 | I19: 0 | J19: 0 | K19: 0 | L19: 0 | M19: 0 | N19: 0 | O19: 0 | P19: 0 | Q19: 0 | R19: 0 | S19: 0 | T19: 0 | U19: 0 | V19: 0 | W19: 0 | X19: 0 | Y19: 0
A20: P460003 | B20: SPRINKLE | C20: 601 | D20: 高效二 | E20: 460 | F20: Amazon com, Inc | G20: 44226 | H20: 43620 | I20: 0 | J20: 0 | K20: 0 | L20: 0 | M20: 0 | N20: 0 | O20: 0 | P20: 0 | Q20: 0 | R20: 0 | S20: 0 | T20: 0 | U20: 0 | V20: 0 | W20: 0 | X20: 0 | Y20: 0
A21: P460004 | B21: POWELL | C21: 601 | D21: 高效二 | E21: 460 | F21: Amazon com, Inc | G21: 44226 | H21: 44410 | I21: 0 | J21: 0 | K21: 0 | L21: 0 | M21: 0 | N21: 0 | O21: 0 | P21: 0 | Q21: 0 | R21: 0 | S21: 0 | T21: 0 | U21: 0 | V21: 0 | W21: 0 | X21: 0 | Y21: 0
A22: P879002 | B22: LIZARD | C22: 601 | D22: 高效二 | E22: C879 | F22: teenage engineering | G22: 45069 | I22: 0 | J22: 0 | K22: 0 | L22: 0 | M22: 0 | N22: 0 | O22: 0 | P22: 0 | Q22: 0 | R22: 0 | S22: 0 | T22: 0 | U22: 0 | V22: 0 | W22: 0 | X22: 0 | Y22: 0
A23: P831007 | B23: MATRIX | C23: 601 | D23: 高效二 | E23: C831 | F23: August Home, Inc. | G23: 45107 | I23: 78155 | J23: 0 | K23: 0 | L23: 0 | M23: 0 | N23: 0 | O23: 0 | P23: 0 | Q23: 0 | R23: 0 | S23: 0 | T23: 0 | U23: 0 | V23: 0 | W23: 0 | X23: 0 | Y23: 0
A24: VIP返利 | C24: 601 | D24: 高效二 | I24: 0 | J24: 0 | K24: 0 | L24: 0 | M24: 0 | N24: 0 | O24: 0 | P24: 0 | Q24: 0 | R24: 0 | S24: 0 | T24: 0 | U24: 0 | V24: 0 | W24: 0 | X24: 0 | Y24: 0
A25: 合计 | I25: =SUM(I3:I24) -> 7383538 | J25: =SUM(J3:J24) -> 0 | K25: =SUM(K3:K24) -> 0 | L25: =SUM(L3:L24) -> 0 | M25: =SUM(M3:M24) -> 0 | N25: =SUM(N3:N24) -> 0 | O25: =SUM(O3:O24) -> 0 | P25: =SUM(P3:P24) -> 0 | ... Y25: =SUM(Y3:Y24) -> 0

Sheet HP3
A1: HP3 2024年1-6月NPI报表明细
A2: 币别:HKD
A3: TK项目号 | B3: 项目名称 | C3: 利润中心 | D3: 事业部 | E3: 终端客户 | F3: 终端客户名称 | G3: 创建日期 | H3: 量产日期 | I3: NPI预算收入 | J3: 注塑模具收入 | K3: 其他模具收入 | L3: 样板费收入 | M3: 夹治具收入 | N3: 其它杂项收入 | O3: 量产前收入 | P3: 注塑模具成本 | Q3: 其他模具成本 | R3: 自费模具摊销 | S3: 量产前夹治具成本 | T3: 试模成本 | U3: 量产前成本 | V3: 量产前收益 | W3: 量产后夹治具成本 | X3: 量产后打样成本 | Y3: 量产后成本 | Z3: 项目收益
A4: P028008 | B4: BOSE SERENA | C4: 701 | D4: 高效三 | E4: 28 | F4: Bose Corporation | G4: 44817 | I4: 7833000 | J4: 886099.17 | K4: 0 | L4: 6538.04 | M4: 0 | N4: 0 | O4: 892637.21 | P4: 755601.88 | Q4: 0 | R4: 0 | S4: 9449.54 | T4: 24946.52 | U4: 789997.94 | V4: 102639.27 | W4: 0 | X4: 30523.4 | Y4: 30523.4 | Z4: =V4-Y4 -> 72115.87
A5: P028009 | B5: SCOTTY | C5: 701 | D5: 高效三 | E5: 28 | F5: Bose Corporation | G5: 44859 | I5: 5958000 | J5: 0 | K5: 0 | L5: 0 | M5: 0 | N5: 0 | O5: 0 | P5: 0 | Q5: 0 | R5: 16188.24 | S5: 7275.35 | T5: 28777.66 | U5: 52241.25 | V5: -52241.25 | W5: 0 | X5: 0 | Y5: 0 | Z5: =V5-Y5 -> -52241.25
A6: P330019 | B6: ERASMUS | C6: 701 | D6: 高效三 | E6: 330 | F6: GN Audio A/S(GSC) | G6: 44226 | H6: 42198 | I6: 5478000 | J6: 391861.44 | K6: 0 | L6: 14898 | M6: 0 | N6: 0 | O6: 406759.44 | P6: 298990.02 | Q6: 0 | R6: 13361.66 | S6: 0 | T6: 0 | U6: 312351.68 | V6: 94407.76 | W6: 5727.88 | X6: 3450.25 | Y6: 9178.13 | Z6: =V6-Y6 -> 85229.63
A7: P330038 | B7: MAPLE | C7: 701 | D7: 高效三 | E7: 330 | F7: GN Audio A/S(GSC) | G7: 44307 | H7: 42198 | I7: 5610000 | J7: 0 | K7: 0 | L7: 0 | M7: 0 | N7: 0 | O7: 0 | P7: 0 | Q7: 0 | R7: 0 | S7: 0 | T7: 0 | U7: 0 | V7: 0 | W7: 0 | X7: 3391.41 | Y7: 3391.41 | Z7: =V7-Y7 -> -3391.41
A8: P330040 | B8: SAMWISE | C8: 701 | D8: 高效三 | E8: 330 | F8: GN Audio A/S(GSC) | G8: 44482 | H8: 44945 | I8: 19323850 | J8: 178849 | K8: 0 | L8: 13557.21 | M8: 0 | N8: 0 | O8: 192406.21 | P8: 106233.68 | Q8: 0 | R8: 9788.82 | S8: 0 | T8: 10150.58 | U8: 126173.08 | V8: 66233.13 | W8: 2079.44 | X8: 425.67 | Y8: 2505.11 | Z8: =V8-Y8 -> 63728.02
A9: P330042 | B9: PILLOW | C9: 701 | D9: 高效三 | E9: 330 | F9: GN Audio A/S(GSC) | G9: 44496 | H9: 44867 | I9: 7104600 | J9: 0 | K9: 0 | L9: 0 | M9: 0 | N9: 0 | O9: 0 | P9: 0 | Q9: 0 | R9: 1845.53 | S9: 0 | T9: 0 | U9: 1845.53 | V9: -1845.53 | W9: 0 | X9: 289.66 | Y9: 289.66 | Z9: =V9-Y9 -> -2135.19
A10: P360016 | B10: ETHEL | C10: 701 | D10: 高效三 | E10: 360 | F10: Google Inc. | G10: 44226 | H10: 42420 | I10: 0 | J10: 0 | K10: 0 | L10: 0 | M10: 0 | N10: 0 | O10: 0 | P10: 0 | Q10: 0 | R10: 0 | S10: 0 | T10: 0 | U10: 0 | V10: 0 | W10: 0 | X10: 0 | Y10: 0 | Z10: =V10-Y10 -> 0
A11: P360021 | B11: SIROCCO | C11: 701 | D11: 高效三 | E11: 360 | F11: Google Inc. | G11: 44357 | H11: 42198 | I11: 0 | J11: 0 | K11: 0 | L11: 0 | M11: 0 | N11: 0 | O11: 0 | P11: 0 | Q11: 0 | R11: 0 | S11: 0 | T11: 0 | U11: 0 | V11: 0 | W11: 0 | X11: 0 | Y11: 0 | Z11: =V11-Y11 -> 0
A12: P360022 | B12: C9 | C12: 701 | D12: 高效三 | E12: 360 | F12: Google Inc. | G12: 44638 | I12: 2420000 | J12: 0 | K12: 0 | L12: 0 | M12: 0 | N12: 0 | O12: 0 | P12: 0 | Q12: 0 | R12: 868.98 | S12: 0 | T12: 0 | U12: 868.98 | V12: -868.98 | W12: 0 | X12: 0 | Y12: 0 | Z12: =V12-Y12 -> -868.98
A13: P404014 | B13: BISMUTH | C13: 701 | D13: 高效三 | E13: 404 | F13: Google Inc | G13: 44334 | H13: 43328 | I13: 67325484 | J13: 2879571.2 | K13: 0 | L13: 10754.37 | M13: 154822 | N13: 0 | O13: 3045147.6 | P13: 2745315.4 | Q13: 0 | R13: 37730.88 | S13: 48258.38 | T13: 53782.04 | U13: 2885086.7 | V13: 160060.83 | W13: 722.22 | X13: 18733.09 | Y13: 19455.31 | Z13: =V13-Y13 -> 140605.52
A14: P435002 | B14: Dublin mid | C14: 701 | D14: 高效三 | E14: 330 | F14: GN Audio A/S(GSC) | G14: 44226 | H14: 42181 | I14: 0 | J14: 0 | K14: 0 | L14: 0 | M14: 0 | N14: 0 | O14: 0 | P14: 0 | Q14: 0 | R14: 0 | S14: 0 | T14: 0 | U14: 0 | V14: 0 | W14: 0 | X14: 0 | Y14: 0 | Z14: =V14-Y14 -> 0
A15: P435004 | B15: Dublin MONO | C15: 701 | D15: 高效三 | E15: 330 | F15: GN Audio A/S(GSC) | G15: 44226 | H15: 42181 | I15: 0 | J15: 0 | K15: 0 | L15: 0 | M15: 0 | N15: 0 | O15: 0 | P15: 0 | Q15: 0 | R15: 0 | S15: 0 | T15: 4489.44 | U15: 4489.44 | V15: -4489.44 | W15: 0 | X15: 62.94 | Y15: 62.94 | Z15: =V15-Y15 -> -4552.38
A16: P435011 | B16: Rio Headset | C16: 701 | D16: 高效三 | E16: 330 | F16: GN Audio A/S(GSC) | G16: 44226 | H16: 43328 | I16: 1491440 | J16: 51892.6 | K16: 0 | L16: 0 | M16: 0 | N16: 0 | O16: 51892.6 | P16: 38122 | Q16: 0 | R16: 0 | S16: 0 | T16: 0 | U16: 38122 | V16: 13770.6 | W16: 0 | X16: 0 | Y16: 0 | Z16: =V16-Y16 -> 13770.6
A17: P818002 | B17: HDT666 | C17: 701 | D17: 高效三 | E17: C818 | F17: 美律电子（深圳）有限公司 | G17: 44757 | I17: 21578100 | J17: 23064.6 | K17: 0 | L17: 1762.11 | M17: 0 | N17: 0 | O17: 24826.71 | P17: 18546.06 | Q17: 0 | R17: 36388.43 | S17: 41718.65 | T17: 15796.86 | U17: 112450 | V17: -87623.29 | W17: 3174.29 | X17: 356.02 | Y17: 3530.31 | Z17: =V17-Y17 -> -91153.6
A18: P330008 | B18: Binary HB | C18: 701 | D18: 高效三 | E18: 330 | F18: GN Audio A/S(GSC) | G18: 44226 | H18: 43266 | I18: 0 | J18: 0 | K18: 0 | L18: 0 | M18: 0 | N18: 0 | O18: 0 | P18: 0 | Q18: 0 | R18: 0 | S18: 0 | T18: 0 | U18: 0 | V18: 0 | W18: 0 | X18: 0 | Y18: 0 | Z18: =V18-Y18 -> 0
A19: P435010 | B19: Rio Base | C19: 701 | D19: 高效三 | E19: 330 | F19: GN Audio A/S(GSC) | G19: 44226 | H19: 42551 | I19: 6333973.8 | J19: 22367.5 | K19: 0 | L19: 0 | M19: 0 | N19: 0 | O19: 22367.5 | P19: 16338 | Q19: 0 | R19: 0 | S19: 0 | T19: 0 | U19: 16338 | V19: 6029.5 | W19: 4385.79 | X19: 0 | Y19: 4385.79 | Z19: =V19-Y19 -> 1643.71
A20: P330007 | B20: Super Mario | C20: 701 | D20: 高效三 | E20: 330 | F20: GN Audio A/S(GSC) | G20: 44226 | H20: 42207 | I20: 0 | J20: 0 | K20: 0 | L20: 0 | M20: 0 | N20: 0 | O20: 0 | P20: 0 | Q20: 0 | R20: 0 | S20: 0 | T20: 0 | U20: 0 | V20: 0 | W20: 0 | X20: 0 | Y20: 0 | Z20: =V20-Y20 -> 0
A21: P360004 | B21: Gotham | C21: 701 | D21: 高效三 | E21: 360 | F21: Google Inc. | G21: 44226 | H21: 43761 | I21: 0 | J21: 0 | K21: 0 | L21: 0 | M21: 0 | N21: 0 | O21: 0 | P21: 0 | Q21: 0 | R21: 0 | S21: 0 | T21: 0 | U21: 0 | V21: 0 | W21: 0 | X21: 0 | Y21: 0 | Z21: =V21-Y21 -> 0
A22: P330009 | B22: Bezos | C22: 701 | D22: 高效三 | E22: 330 | F22: GN Audio A/S(GSC) | G22: 44226 | H22: 43577 | I22: 0 | J22: 0 | K22: 0 | L22: 0 | M22: 0 | N22: 0 | O22: 0 | P22: 0 | Q22: 0 | R22: 8788.13 | S22: 0 | T22: 0 | U22: 8788.13 | V22: -8788.13 | W22: 0 | X22: 0 | Y22: 0 | Z22: =V22-Y22 -> -8788.13
A23: P330006 | B23: Rio Base 2 | C23: 701 | D23: 高效三 | E23: 330 | F23: GN Audio A/S(GSC) | G23: 44226 | H23: 43329 | I23: 338772.5 | J23: 142202.84 | K23: 0 | L23: 0 | M23: 0 | N23: 0 | O23: 142202.84 | P23: 115144 | Q23: 0 | R23: 0 | S23: 0 | T23: 0 | U23: 115144 | V23: 27058.84 | W23: 0 | X23: 2763.2 | Y23: 2763.2 | Z23: =V23-Y23 -> 24295.64
A24: P293011 | B24: Jbay | C24: 701 | D24: 高效三 | E24: 293 | F24: GoPro, Inc. | G24: 44226 | H24: 43717 | I24: 0 | J24: 0 | K24: 0 | L24: 0 | M24: 0 | N24: 0 | O24: 0 | P24: 0 | Q24: 0 | R24: 0 | S24: 0 | T24: 0 | U24: 0 | V24: 0 | W24: 0 | X24: 0 | Y24: 0 | Z24: =V24-Y24 -> 0
A25: P330010 | B25: Spiderman | C25: 701 | D25: 高效三 | E25: 330 | F25: GN Audio A/S(GSC) | G25: 0 | H25: 0 | I25: 0 | J25: 0 | K25: 0 | L25: 0 | M25: 0 | N25: 0 | O25: 0 | P25: 0 | Q25: 0 | R25: 0 | S25: 0 | T25: 0 | U25: 0 | V25: 0 | W25: 0 | X25: 0 | Y25: 0 | Z25: =V25-Y25 -> 0
A26: P821002 | B26: S3 | C26: 701 | D26: 高效三 | E26: C821 | F26: Square Inc. | G26: 44226 | H26: 44133 | I26: 0 | J26: 0 | K26: 0 | L26: 0 | M26: 0 | N26: 0 | O26: 0 | P26: 0 | Q26: 0 | R26: 17857.79 | S26: 0 | T26: 0 | U26: 17857.79 | V26: -17857.79 | W26: 1002.37 | X26: 117.61 | Y26: 1119.98 | Z26: =V26-Y26 -> -18977.77
A27: P821003 | B27: S3 MOUNT | C27: 701 | D27: 高效三 | E27: C821 | F27: Square Inc. | G27: 44480 | I27: 2180000 | J27: 0 | K27: 0 | L27: 0 | M27: 0 | N27: 0 | O27: 0 | P27: 0 | Q27: 0 | R27: 9094.98 | S27: 0 | T27: 0 | U27: 9094.98 | V27: -9094.98 | W27: 0 | X27: 0 | Y27: 0 | Z27: =V27-Y27 -> -9094.98
A28: P821004 | B28: S3B | C28: 701 | D28: 高效三 | E28: C821 | F28: Square Inc. | G28: 44894 | I28: 2622471.5 | J28: 0 | K28: 0 | L28: 0 | M28: 0 | N28: 0 | O28: 0 | P28: 0 | Q28: 0 | R28: 72331.91 | S28: 369.37 | T28: 21418.57 | U28: 94119.85 | V28: -94119.85 | W28: 0 | X28: 0 | Y28: 0 | Z28: =V28-Y28 -> -94119.85
